Workbook

Sheet SUMMARY
A14: Project name : | B14: PROPOSED THREE STORY RESIDENCE
A15: Location : | B15: GRAND CENTENIAL HOMES KAWIT CAVITE
A16: Date : | B16: =TODAY() -> 46251
C18: Total Area: | D18: 387.9 | E18: sq.m | Q18: 3500 | R18: water cs
A19: ITEM NO | B19: WORK ITEM DESCRIPTION | C19: Total Amount Php | D19: Cost per Sq.m | E19: Weighted % age | F19: AMOUNT | L19: PERCENTAGE ACCOMPLISHMENT | O19: BALANCE AMOUNT | Q19: 2000 | R19: shower
A20: A | B20: GENERAL REQUIREMENTS | F20: THIS DATE | G20: 1900000 | L20: PREVIOUS | M20: THIS DATE | N20: TO DATE
B21: General Requirements Sub-total: | C21: =BOQ!I31 -> 599000 | D21: =C21/$D$18 -> 1544.2124 | E21: =C21/$C$39 -> 0.065068215 | F21: =BOQ!V31 -> 157250 | L21: =SUM(BOQ!AU31:BB31) -> 0.5 | M21: =F21/C21 -> 0.26252087 | N21: =L21+M21 -> 0.76252087 | O21: =C21-(N21*C21) -> 142250
A22: B | B22: ARCHITECTURAL WORKS
B23: Ceiling Finish | C23: =BOQ!$I$167 -> 942300.44 | D23: =C23/$D$18 -> 2429.2355 | E23: =C23/$C$39 -> 0.10236028 | F23: =BOQ!V167 -> 134756.63 | G23: =G20/C26 -> 0.78448388 | H23: =1-G23 -> 0.21551612 | J23: =SUM(C23:C27)*0.15 -> 1100379.8 | L23: =SUM(BOQ!AU167:BB167) -> 0.86075455 | M23: =BOQ!Y167 -> 0.13920009 | N23: =M23+L23 -> 0.99995465 | O23: =C23-(N23*C23) -> 42.734714
B24: Floor Finish | C24: =BOQ!I232 -> 368899.08 | D24: =C24/$D$18 -> 951.01593 | E24: =C24/$C$39 -> 0.040072796 | F24: =BOQ!V232 -> 77840.03 | L24: =SUM(BOQ!AU232:BB232) -> 0.8425 | M24: 0.09 | N24: =M24+L24 -> 0.9325 | O24: =C24-(N24*C24) -> 24900.688
B25: Wall Finish | C25: =wall!I127 -> 2040984.2 | D25: =C25/$D$18 -> 5261.6246 | E25: =C25/$C$39 -> 0.22170818 | F25: =wall!V127 -> 655611.9 | G25: =C26*H23 -> 521974.57 | L25: =SUM(wall!BB127:BI127) -> 0.32323129 | M25: =wall!Y127 -> 0.34305442 | N25: =M25+L25 -> 0.66628571 | O25: =C25-(N25*C25) -> 681105.58
B26: Cabinet's | C26: =SUM(CABINETS!I68,CABINETS!I155,CABINETS!I238) -> 2421974.6 | D26: =C26/$D$18 -> 6243.8117 | E26: =C26/$C$39 -> 0.26309443 | F26: =CABINETS!AD239 -> 996590.5 | L26: =SUM(CABINETS!BC239:BJ239) -> 0.12028571 | M26: =CABINETS!AG239 -> 0.36208466 | N26: =M26+L26 -> 0.48237037 | O26: =C26-(N26*C26) -> 1253685.8
B27: Door's and Window's | C27: ='DOORS & WINDOW, PLUMBING, WOODE'!H56 -> 1561707.2 | D27: =C27/$D$18 -> 4026.0562 | E27: =C27/$C$39 -> 0.16964524 | F27: ='DOORS & WINDOW, PLUMBING, WOODE'!O56 -> 241863.6 | L27: =SUM('DOORS & WINDOW, PLUMBING, WOODE'!AN56:AU56) -> 0.54761905 | M27: ='DOORS & WINDOW, PLUMBING, WOODE'!R56 -> 0.047619048 | N27: =M27+L27 -> 0.5952381 | O27: =C27-(N27*C27) -> 632119.58
B28: Architectural Sub-total: | C28: =SUM(C23:C27) -> 7335865.5 | D28: =SUM(D23:D27) -> 18911.744 | E28: =SUM(E23:E27) -> 0.79688092 | F28: =SUM(F23:F27) -> 2106662.7 | G28: =SUM(G23:G27) -> 521975.36 | H28: =SUM(H23:H27) -> 0.21551612 | I28: =SUM(I23:I27) -> 0 | J28: =SUM(J23:J27) -> 1100379.8 | K28: =SUM(K23:K27) -> 0 | L28: =SUM(L23:L27)/COUNT(L23:L27) -> 0.53887812 | M28: =SUM(M23:M27)/COUNT(M23:M27) -> 0.19639164 | N28: =SUM(N23:N27)/COUNT(N23:N27) -> 0.73526977 | O28: =SUM(O23:O27) -> 2591854.4
A29: C | B29: PLUMBING WORKS
B30: Plumbing Fixtures | C30: ='DOORS & WINDOW, PLUMBING, WOODE'!H66 -> 56500 | D30: =C30/$D$18 -> 145.6561 | E30: =C30/$C$39 -> 0.0061374861 | F30: ='DOORS & WINDOW, PLUMBING, WOODE'!O66 -> 0 | L30: =SUM('DOORS & WINDOW, PLUMBING, WOODE'!AN66:AU66) -> 0 | M30: ='DOORS & WINDOW, PLUMBING, WOODE'!R66/C30 -> 0 | N30: =M30+L30 -> 0 | O30: =C30-(N30*C30) -> 56500
B31: Plumbing Sub-total: | C31: =SUM(C30) -> 56500 | D31: =SUM(D30) -> 145.6561 | E31: =SUM(E30) -> 0.0061374861 | F31: =SUM(F30) -> 0 | G31: =SUM(G30) -> 0 | H31: =SUM(H30) -> 0 | I31: =SUM(I30) -> 0 | J31: =SUM(J30) -> 0 | ... O31: =SUM(O30) -> 56500
A32: D | B32: ELECTRICAL WORKS
B33: Lighting Fixtures | C33: =ELECTRICAL!I41 -> 607624 | D33: =C33/$D$18 -> 1566.445 | E33: =C33/$C$39 -> 0.066005024 | F33: =ELECTRICAL!Z41 -> 121524.8 | L33: =SUM(ELECTRICAL!AY41:BF41) -> 0 | M33: =ELECTRICAL!AC41 -> 0.2 | N33: =M33+L33 -> 0.2 | O33: =C33-(N33*C33) -> 486099.2
B34: Switches | C34: =ELECTRICAL!I29 -> 38841 | D34: =C34/$D$18 -> 100.13148 | E34: =C34/$C$39 -> 0.0042192229 | F34: =ELECTRICAL!Z29 -> 14368.75 | L34: =SUM(ELECTRICAL!AY29:BF29) -> 0 | M34: =ELECTRICAL!AC29 -> 0.36666667 | N34: =M34+L34 -> 0.36666667 | O34: =C34-(N34*C34) -> 24599.3
B35: Outlets | C35: =ELECTRICAL!I24 -> 66825 | D35: =C35/$D$18 -> 172.27378 | E35: =C35/$C$39 -> 0.0072590709 | F35: =ELECTRICAL!Z24 -> 26730 | G35: =C26+C23+C24+C25+C27 -> 7335865.5 | L35: =SUM(ELECTRICAL!AY24:BF24) -> 0 | M35: =ELECTRICAL!AC24 -> 0.4 | N35: =M35+L35 -> 0.4 | O35: =C35-(N35*C35) -> 40095
B36: Wires | C36: =ELECTRICAL!I49 -> 375412.68 | D36: =C36/$D$18 -> 967.80788 | E36: =C36/$C$39 -> 0.040780355 | F36: =ELECTRICAL!Z49 -> 96533.403 | L36: =SUM(ELECTRICAL!AY49:BF49) -> 0.6975 | M36: =ELECTRICAL!AC49 -> 0.2125 | N36: =M36+L36 -> 0.91 | O36: =C36-(N36*C36) -> 33787.141
B37: Panel Board | C37: =ELECTRICAL!I77 -> 125655.42 | D37: =C37/$D$18 -> 323.93766 | E37: =C37/$C$39 -> 0.013649706 | F37: =ELECTRICAL!Z77 -> 13471.7 | L37: =SUM(ELECTRICAL!AY77:BF77) -> 0 | M37: =ELECTRICAL!AC77 -> 0.083333333 | N37: =M37+L37 -> 0.083333333 | O37: =C37-(N37*C37) -> 115184.13
B38: Electrical Sub-total: | C38: =SUM(C33:C37) -> 1214358.1 | D38: =C38/$D$18 -> 3130.5958 | E38: =SUM(E33:E37) -> 0.13191338 | F38: =ELECTRICAL!Z78 -> 272628.65 | G38: =ELECTRICAL!AA78 -> 272628.65 | H38: =ELECTRICAL!AB78 -> 941729.44 | I38: =ELECTRICAL!AC78 -> 0.2525 | J38: =ELECTRICAL!AD78 -> 0 | K38: =ELECTRICAL!AE78 -> 0 | L38: =SUM(L33:L37)/COUNT(L33:L37) -> 0.1395 | M38: =SUM(M33:M37)/COUNT(M33:M37) -> 0.2525 | N38: =SUM(N33:N37)/COUNT(N33:N37) -> 0.392 | O38: =SUM(O33:O37) -> 699764.78
B39: Direct Sub-Total: | C39: =SUM(C31,C38,C28,C21) -> 9205723.6 | D39: =SUM(D31,D38,D28,D21) -> 23732.208 | E39: =SUM(E31,E38,E28,E21) -> 1 | F39: =SUM(F31,F38,F28,F21) -> 2536541.3 | G39: =SUM(G31,G38,G28,G21) -> 794604.01 | H39: =SUM(H31,H38,H28,H21) -> 941729.66 | I39: =SUM(I31,I38,I28,I21) -> 0.2525 | J39: =SUM(J31,J38,J28,J21) -> 1100379.8 | K39: =SUM(K31,K38,K28,K21) -> 0 | L39: =SUM(L31,L38,L28,L21)/4 -> 0.29459453 | M39: =SUM(M31,M38,M28,M21)/4 -> 0.17785313 | N39: =SUM(N31,N38,N28,N21)/4 -> 0.47244766 | O39: =SUM(O31,O38,O28,O21) -> 3490369.2
B40: Profit 7%: | C40: =C39*0.07 -> 644400.65 | F40: =M40*C40 -> 114608.67 | L40: =$L$39 -> 0.29459453 | M40: =$M$39 -> 0.17785313 | N40: =$N$39 -> 0.47244766 | O40: =C40-(N40*C40) -> 339955.07
B41: OCM 8%: | C41: =C39*0.08 -> 736457.88 | F41: =M41*C41 -> 130981.34 | J41: =(C40+C41)*0.92 -> 1270389.9 | L41: =$L$39 -> 0.29459453 | M41: =$M$39 -> 0.17785313 | N41: =$N$39 -> 0.47244766 | O41: =C41-(N41*C41) -> 388520.08
B42: Indirect Total Cost: | C42: =SUM(C39:C41) -> 10586582 | D42: =C42/$D$18 -> 27292.039 | E42: =SUM($E$38,$E$31,$E$28,$E$21) -> 1 | F42: =M42*C42 -> 1882856.7 | G42: =SUM(G39:G41) -> 794604.01 | H42: =SUM(H39:H41) -> 941729.66 | I42: =SUM(I39:I41) -> 0.2525 | J42: =SUM(J39:J41) -> 2370769.7 | K42: =SUM(K39:K41) -> 0 | L42: =L39 -> 0.29459453 | M42: =M39 -> 0.17785313 | N42: =N39 -> 0.47244766 | O42: =SUM(O39:O41) -> 4218844.3
B43: DISCOUNTED AMOUNT: | C43: 10300000 | D43: =C43/$D$18 -> 26553.235 | E43: =SUM($E$38,$E$31,$E$28,$E$21) -> 1 | F43: =M43*C43 -> 1831887.2 | G43: Overall Profit: | I43: =I40+J42 -> 2370769.7 | L43: =L39 -> 0.29459453 | M43: =M39 -> 0.17785313 | N43: =N39 -> 0.47244766 | O43: =C43-(N43*C43) -> 5433789.1
A45: BILLING SUMMARY
B46: PREVIOUS | C46: THIS DATE | D46: TO DATE | AB46: =C43*0.3 -> 3090000
A47: CONTRACT AMOUNT | B47: =C43*L43 -> 3034323.7 | C47: =F43 -> 1831887.2 | D47: =SUM(B47:C47) -> 4866210.9
A48: DEDUCTIONS | AB48: =D47+E47 -> 4866210.9
A49: RETENTION 5% | B49: =-$B$47*0.05 -> -151716.18 | C49: =-C47*0.05 -> -91594.361 | D49: =SUM(B49:C49) -> -243310.54 | AB49: =C43-AB48 -> 5433789.1
A50: RECOUPMENT 30% | B50: =-$B$47*0.3 -> -910297.1 | C50: =-C47*0.3 -> -549566.17 | D50: =SUM(B50:C50) -> -1459863.3
A51: TOTAL BILLING THIS DATE | B51: =SUM(B47:B50) -> 1972310.4 | C51: =SUM(C47:C50) -> 1190726.7 | D51: =SUM(B51:C51) -> 3163037.1
A52: %AGE BILLING THIS DATE | B52: =B47/$C$43 -> 0.29459453 | C52: =C47/$C$43 -> 0.17785313 | D52: =SUM(B52:C52) -> 0.47244766
A54: Remaining To Bill
A55: Billing no. 2 | B55: 21759.23
A56: Total : | B56: =SUM(B55:B55) -> 21759.23
...

Sheet BOQ
A15: Project name : | B15: PROPOSED THREE STORY RESIDENCE
A16: Location : | B16: GRAND CENTENIAL HOMES KAWIT CAVITE
A17: Date : | B17: =TODAY() -> 46251
AA18: QUANTITY | AJ18: AMOUNT | AS18: ACCOMPLISHMENT | AU18: PREVIOUS ACCOMPLISHMENT
A19: ITEM NO | B19: Description | C19: QUANTITY | D19: QUANTITY | E19: UNIT | F19: Material Cost Php/unit | G19: Labor and Equipment Cost Php/unit | H19: Total Cost Php/Unit | I19: Total Amount Php | Q19: QUANTITY | U19: AMOUNT | Y19: PERCENTAGE | AA19: BILLING 1 | AB19: BILLING 2 | AC19: BILLING 3 | AD19: BILLING 4 | AE19: BILLING 5 | AF19: BILLING 6 | AG19: BILLING 7 | AH19: BILLING 8 | AJ19: BILLING 1 | AK19: BILLING 2 | AL19: BILLING 3 | AM19: BILLING 4 | AN19: BILLING 5 | AO19: BILLING 6 | AP19: BILLING 7 | AQ19: BILLING 8 | AS19: BILLING 1 | AU19: BILLING 1 | AV19: BILLING 2 | AW19: BILLING 3 | AX19: BILLING 4 | AY19: BILLING 5 | AZ19: BILLING 6 | BA19: BILLING 7 | BB19: BILLING 8
A20: A | B20: GENERAL REQUIREMENTS | Q20: PREVIOUS | R20: THIS DATE | S20: TO DATE | T20: BALANCE | U20: PREVIOUS | V20: THIS DATE | W20: TO DATE | X20: BALANCE | Y20: Accomplishment
B21: Mobilization/Demobilization | C21: 1 | D21: 1 | E21: lot
B22: Site Management | C22: 10 | D22: 8 | E22: month/s | G22: 35000 | H22: =SUM(F22:G22) -> 35000 | I22: =H22*D22 -> 280000 | Q22: =SUM(AA22:AH22) -> 2.4 | R22: =Y22*D22 -> 2 | S22: =SUM(Q22:R22) -> 4.4 | T22: =D22-S22 -> 3.6 | U22: =SUM(AJ21:AQ21) -> 0 | V22: =Y22*I22 -> 70000 | W22: =SUM(U22:V22) -> 70000 | X22: =I22-W22 -> 210000 | Y22: =SUM(AS22) -> 0.25 | AA22: 2.4 | AJ22: 84000 | AS22: 0.25 | AU22: 0.3 | AV22: 0.2
B23: Government Permits and Taxes | C23: 1 | E23: lot | G23: by owner | H23: by owner
B24: Services and Utilities | C24: 10 | D24: 8 | E24: month/s | G24: 8000 | H24: =SUM(F24:G24) -> 8000 | I24: =H24*D24 -> 64000 | Q24: =SUM(AA24:AH24) -> 2.4 | R24: =Y24*D24 -> 2 | S24: =SUM(Q24:R24) -> 4.4 | T24: =D24-S24 -> 3.6 | U24: =SUM(AJ23:AQ23) -> 0 | V24: =Y24*I24 -> 16000 | W24: =SUM(U24:V24) -> 16000 | X24: =I24-W24 -> 48000 | Y24: =SUM(AS24) -> 0.25 | AA24: 2.4 | AJ24: 19200 | AS24: 0.25 | AU24: 0.3 | AV24: 0.2
B25: Temporary Facilities | C25: 10 | D25: 8 | E25: month/s | G25: 15000 | H25: =SUM(F25:G25) -> 15000 | I25: =H25*D25 -> 120000 | Q25: =SUM(AA25:AH25) -> 2.4 | R25: =Y25*D25 -> 2 | S25: =SUM(Q25:R25) -> 4.4 | T25: =D25-S25 -> 3.6 | U25: =SUM(AJ24:AQ24) -> 19200 | V25: =Y25*I25 -> 30000 | W25: =SUM(U25:V25) -> 49200 | X25: =I25-W25 -> 70800 | Y25: =SUM(AS25) -> 0.25 | AA25: 2.4 | AJ25: 36000 | AS25: 0.25 | AU25: 0.3 | AV25: 0.2
B26: Engineering plans, Shop Drawings & Asbuilt | C26: 1 | D26: 1 | E26: lot | G26: - | H26: DISCOUNTED
B27: Hauling and Disposal | C27: 1 | D27: 1 | E27: lot | G27: 60000 | H27: =SUM(F27:G27) -> 60000 | I27: =H27*D27 -> 60000 | Q27: =SUM(AA27:AH27) -> 0.3 | R27: =Y27*D27 -> 0.25 | S27: =SUM(Q27:R27) -> 0.55 | T27: =D27-S27 -> 0.45 | U27: =SUM(AJ26:AQ26) -> 0 | V27: =Y27*I27 -> 15000 | W27: =SUM(U27:V27) -> 15000 | X27: =I27-W27 -> 45000 | Y27: =SUM(AS27) -> 0.25 | AA27: 0.3 | AJ27: 18000 | AS27: 0.25 | AU27: 0.3 | AV27: 0.2
B28: Housekeeping | C28: 1 | D28: 1 | E28: lot | H28: Included
B29: Safety | C29: 1 | D29: 1 | E29: lot | H29: Included
B30: Scaffolding | C30: 1 | D30: 1 | E30: lot | G30: 75000 | H30: =SUM(F30:G30) -> 75000 | I30: =H30*D30 -> 75000 | Q30: =SUM(AA30:AH30) -> 0.3 | R30: =Y30*D30 -> 0.35 | S30: =SUM(Q30:R30) -> 0.65 | T30: =D30-S30 -> 0.35 | U30: =SUM(AJ29:AQ29) -> 0 | V30: =Y30*I30 -> 26250 | W30: =SUM(U30:V30) -> 26250 | X30: =I30-W30 -> 48750 | Y30: =SUM(AS30) -> 0.35 | AA30: 0.3 | AJ30: 22500 | AS30: 0.35 | AU30: 0.3 | AV30: 0.2
B31: General Requirements Sub-total: | I31: =SUM(I21:I30) -> 599000 | Q31: =SUM(Q22:Q30) -> 7.8 | R31: =SUM(R22:R30) -> 6.6 | S31: =SUM(S22:S30) -> 14.4 | T31: =SUM(T22:T30) -> 11.6 | U31: =SUM(U22:U30) -> 19200 | V31: =SUM(V22:V30) -> 157250 | W31: =SUM(W22:W30) -> 176450 | X31: =SUM(X22:X30) -> 422550 | Y31: =SUM(Y22:Y30)/COUNT(Y22:Y30) -> 0.27 | AA31: 7.8 | AJ31: 179700 | AU31: 0.3 | AV31: =SUM(AV22:AV30)/COUNT(AV22:AV30) -> 0.2
A32: B | B32: ARCHITECTURAL WORKS
B33: Ceiling Finish
B34: Ground Floor (Interior)
B35: HALLWAY, LIVING, DINING TO KITCHEN AREA | M35: 60.4
B36: Gypsum Board | C36: 88.72 | D36: =C36*$K$39 -> 97.592 | E36: sq.m | F36: ='Material and Labor Cost'!$D$8 -> 250 | G36: ='Material and Labor Cost'!$F$8 -> 350 | H36: =SUM(F36:G36) -> 600 | I36: =H36*D36 -> 58555.2 | M36: =C36/M35 -> 1.4688742 | Q36: =SUM(AA36:AH36) -> 48.796 | R36: =Y36*D36 -> 9.7592 | S36: =SUM(Q36:R36) -> 58.5552 | T36: =D36-S36 -> 39.0368 | U36: =SUM(AJ35:AQ35) -> 0 | V36: =Y36*I36 -> 5855.52 | W36: =SUM(U36:V36) -> 5855.52 | X36: =I36-W36 -> 52699.68 | Y36: =SUM(AS36) -> 0.1 | AA36: 48.796 | AJ36: 29277.6 | AS36: 0.1 | AU36: 0.5 | AV36: 0.4
B37: CARRYING channel | C37: =45*$M$36 -> 66.099338 | D37: =C37*$K$39 -> 72.709272 | E37: l.m | F37: ='Material and Labor Cost'!$D$9 -> 126.5 | G37: ='Material and Labor Cost'!$F$9 -> 70 | H37: =SUM(F37:G37) -> 196.5 | I37: =H37*D37 -> 14287.372 | N37: 85 | Q37: =SUM(AA37:AH37) -> 36.354636 | R37: =Y37*D37 -> 7.2709272 | S37: =SUM(Q37:R37) -> 43.625563 | T37: =D37-S37 -> 29.083709 | U37: =SUM(AJ36:AQ36) -> 29277.6 | V37: =Y37*I37 -> 1428.7372 | W37: =SUM(U37:V37) -> 30706.337 | X37: =I37-W37 -> -16418.965 | Y37: =SUM(AS37) -> 0.1 | AA37: 36.354636 | AJ37: 7143.6859 | AS37: 0.1 | AU37: 0.5 | AV37: 0.4
B38: Metal Furring | C38: =N37*$M$36 -> 124.8543 | D38: =C38*$K$39 -> 137.33974 | E38: l.m | F38: ='Material and Labor Cost'!$D$10 -> 126.5 | G38: ='Material and Labor Cost'!$F$10 -> 70 | H38: =SUM(F38:G38) -> 196.5 | I38: =H38*D38 -> 26987.258 | K38: Multiplier Mark up | N38: 30 | Q38: =SUM(AA38:AH38) -> 68.669868 | R38: =Y38*D38 -> 13.733974 | S38: =SUM(Q38:R38) -> 82.403841 | T38: =D38-S38 -> 54.935894 | U38: =SUM(AJ37:AQ37) -> 7143.6859 | V38: =Y38*I38 -> 2698.7258 | W38: =SUM(U38:V38) -> 9842.4117 | X38: =I38-W38 -> 17144.846 | Y38: =SUM(AS38) -> 0.1 | AA38: 68.669868 | AJ38: 13493.629 | AS38: 0.1 | AU38: 0.5 | AV38: 0.4
B39: Hanger clips | C39: =N38*$M$36 -> 44.066225 | D39: =ROUNDUP(C39*$K$39,0) -> 49 | E39: pcs | F39: ='Material and Labor Cost'!$D$11 -> 30 | G39: ='Material and Labor Cost'!$F$11 -> 20 | H39: =SUM(F39:G39) -> 50 | I39: =H39*D39 -> 2450 | K39: 1.1 | N39: 110 | Q39: =SUM(AA39:AH39) -> 24.5 | R39: =Y39*D39 -> 4.9 | S39: =SUM(Q39:R39) -> 29.4 | T39: =D39-S39 -> 19.6 | U39: =SUM(AJ38:AQ38) -> 13493.629 | V39: =Y39*I39 -> 245 | W39: =SUM(U39:V39) -> 13738.629 | X39: =I39-W39 -> -11288.629 | Y39: =SUM(AS39) -> 0.1 | AA39: 24.5 | AJ39: 1225 | AS39: 0.1 | AU39: 0.5 | AV39: 0.4
B40: W clips | C40: =N39*$M$36 -> 161.57616 | D40: =ROUNDUP(C40*$K$39,0) -> 178 | E40: pcs | F40: ='Material and Labor Cost'!$D$12 -> 10 | G40: ='Material and Labor Cost'!$F$12 -> 20 | H40: =SUM(F40:G40) -> 30 | I40: =H40*D40 -> 5340 | N40: 46.32 | Q40: =SUM(AA40:AH40) -> 89 | R40: =Y40*D40 -> 17.8 | S40: =SUM(Q40:R40) -> 106.8 | T40: =D40-S40 -> 71.2 | U40: =SUM(AJ39:AQ39) -> 1225 | V40: =Y40*I40 -> 534 | W40: =SUM(U40:V40) -> 1759 | X40: =I40-W40 -> 3581 | Y40: =SUM(AS40) -> 0.1 | AA40: 89 | AJ40: 2670 | AS40: 0.1 | AU40: 0.5 | AV40: 0.4
B41: Wall Angle | C41: =N40*$M$36 -> 68.038252 | D41: =ROUNDUP(C41*$K$39,0) -> 75 | E41: l.m | F41: ='Material and Labor Cost'!$D$13 -> 110 | G41: ='Material and Labor Cost'!$F$13 -> 60 | H41: =SUM(F41:G41) -> 170 | I41: =H41*D41 -> 12750 | Q41: =SUM(AA41:AH41) -> 37.5 | R41: =Y41*D41 -> 7.5 | S41: =SUM(Q41:R41) -> 45 | T41: =D41-S41 -> 30 | U41: =SUM(AJ40:AQ40) -> 2670 | V41: =Y41*I41 -> 1275 | W41: =SUM(U41:V41) -> 3945 | X41: =I41-W41 -> 8805 | Y41: =SUM(AS41) -> 0.1 | AA41: 37.5 | AJ41: 6375 | AS41: 0.1 | AU41: 0.5 | AV41: 0.4
K42: Miscellaneous
B43: POWDER ROOM
B44: Ficem Board | C44: 4 | D44: =C44*$K$39 -> 4.4 | E44: sq.m | F44: ='Material and Labor Cost'!$D$18 -> 250 | G44: ='Material and Labor Cost'!$F$18 -> 350 | H44: =SUM(F44:G44) -> 600 | I44: =H44*D44 -> 2640 | K44: 0.05 | Q44: =SUM(AA44:AH44) -> 1.32 | R44: =Y44*D44 -> 1.276 | S44: =SUM(Q44:R44) -> 2.596 | T44: =D44-S44 -> 1.804 | U44: =SUM(AJ43:AQ43) -> 0 | V44: =Y44*I44 -> 765.6 | W44: =SUM(U44:V44) -> 765.6 | X44: =I44-W44 -> 1874.4 | Y44: =SUM(AS44) -> 0.29 | AA44: 1.32 | AJ44: 792 | AS44: 0.29 | AU44: 0.3 | AV44: 0.4
B45: CARRYING channel | C45: 3.3333333 | D45: =C45*$K$39 -> 3.6666667 | E45: l.m | F45: ='Material and Labor Cost'!$D$9 -> 126.5 | G45: ='Material and Labor Cost'!$F$9 -> 70 | H45: =SUM(F45:G45) -> 196.5 | I45: =H45*D45 -> 720.5 | Q45: =SUM(AA45:AH45) -> 1.1 | R45: =Y45*D45 -> 1.0633333 | S45: =SUM(Q45:R45) -> 2.1633333 | T45: =D45-S45 -> 1.5033333 | U45: =SUM(AJ44:AQ44) -> 792 | V45: =Y45*I45 -> 208.945 | W45: =SUM(U45:V45) -> 1000.945 | X45: =I45-W45 -> -280.445 | Y45: =SUM(AS45) -> 0.29 | AA45: 1.1 | AJ45: 216.15 | AS45: 0.29 | AU45: 0.3 | AV45: 0.4
B46: Metal Furring | C46: 6.6666667 | D46: =C46*$K$39 -> 7.3333333 | E46: l.m | F46: ='Material and Labor Cost'!$D$10 -> 126.5 | G46: ='Material and Labor Cost'!$F$10 -> 70 | H46: =SUM(F46:G46) -> 196.5 | I46: =H46*D46 -> 1441 | Q46: =SUM(AA46:AH46) -> 2.2 | R46: =Y46*D46 -> 2.1266667 | S46: =SUM(Q46:R46) -> 4.3266667 | T46: =D46-S46 -> 3.0066667 | U46: =SUM(AJ45:AQ45) -> 216.15 | V46: =Y46*I46 -> 417.89 | W46: =SUM(U46:V46) -> 634.04 | X46: =I46-W46 -> 806.96 | Y46: =SUM(AS46) -> 0.29 | AA46: 2.2 | AJ46: 432.3 | AS46: 0.29 | AU46: 0.3 | AV46: 0.4
B47: Hanger clips | C47: 4 | D47: =ROUNDUP(C47*$K$39,0) -> 5 | E47: pcs | F47: ='Material and Labor Cost'!$D$11 -> 30 | G47: ='Material and Labor Cost'!$F$11 -> 20 | H47: =SUM(F47:G47) -> 50 | I47: =H47*D47 -> 250 | Q47: =SUM(AA47:AH47) -> 1.5 | R47: =Y47*D47 -> 1.45 | S47: =SUM(Q47:R47) -> 2.95 | T47: =D47-S47 -> 2.05 | U47: =SUM(AJ46:AQ46) -> 432.3 | V47: =Y47*I47 -> 72.5 | W47: =SUM(U47:V47) -> 504.8 | X47: =I47-W47 -> -254.8 | Y47: =SUM(AS47) -> 0.29 | AA47: 1.5 | AJ47: 75 | AS47: 0.29 | AU47: 0.3 | AV47: 0.4
B48: W clips | C48: 12 | D48: =ROUNDUP(C48*$K$39,0) -> 14 | E48: pcs | F48: ='Material and Labor Cost'!$D$12 -> 10 | G48: ='Material and Labor Cost'!$F$12 -> 20 | H48: =SUM(F48:G48) -> 30 | I48: =H48*D48 -> 420 | Q48: =SUM(AA48:AH48) -> 4.2 | R48: =Y48*D48 -> 4.06 | S48: =SUM(Q48:R48) -> 8.26 | T48: =D48-S48 -> 5.74 | U48: =SUM(AJ47:AQ47) -> 75 | V48: =Y48*I48 -> 121.8 | W48: =SUM(U48:V48) -> 196.8 | X48: =I48-W48 -> 223.2 | Y48: =SUM(AS48) -> 0.29 | AA48: 4.2 | AJ48: 126 | AS48: 0.29 | AU48: 0.3 | AV48: 0.4
B49: Wall Angle | C49: 7 | D49: =ROUNDUP(C49*$K$39,0) -> 8 | E49: l.m | F49: ='Material and Labor Cost'!$D$13 -> 110 | G49: ='Material and Labor Cost'!$F$13 -> 60 | H49: =SUM(F49:G49) -> 170 | I49: =H49*D49 -> 1360 | Q49: =SUM(AA49:AH49) -> 2.4 | R49: =Y49*D49 -> 2.32 | S49: =SUM(Q49:R49) -> 4.72 | T49: =D49-S49 -> 3.28 | U49: =SUM(AJ48:AQ48) -> 126 | V49: =Y49*I49 -> 394.4 | W49: =SUM(U49:V49) -> 520.4 | X49: =I49-W49 -> 839.6 | Y49: =SUM(AS49) -> 0.29 | AA49: 2.4 | AJ49: 408 | AS49: 0.29 | AU49: 0.3 | AV49: 0.4
B51: Paint flat finish | C51: =(C36+C44)*2 -> 185.44 | D51: =C51*$K$39 -> 203.984 | E51: sq.m | F51: ='Material and Labor Cost'!$D$14 -> 250 | G51: ='Material and Labor Cost'!$F$14 -> 350 | H51: =SUM(F51:G51) -> 600 | I51: =H51*D51 -> 122390.4 | Q51: =SUM(AA51:AH51) -> 61.1952 | R51: =Y51*D51 -> 59.15536 | S51: =SUM(Q51:R51) -> 120.35056 | T51: =D51-S51 -> 83.63344 | U51: =SUM(AJ50:AQ50) -> 0 | V51: =Y51*I51 -> 35493.216 | W51: =SUM(U51:V51) -> 35493.216 | X51: =I51-W51 -> 86897.184 | Y51: =SUM(AS51) -> 0.29 | AA51: 61.1952 | AJ51: 36717.12 | AS51: 0.29 | AU51: 0.3 | AV51: 0.4
B53: Ground Floor (Exterior)
B54: PVC ceiling Panel | C54: 39 | D54: =C54*$K$39 -> 42.9 | E54: sq.m | F54: ='Material and Labor Cost'!$D$15 -> 250 | G54: ='Material and Labor Cost'!$F$15 -> 350 | H54: =SUM(F54:G54) -> 600 | I54: =H54*D54 -> 25740 | M54: 39 | N54: 24.5 | Q54: =SUM(AA54:AH54) -> 21.45 | R54: =Y54*D54 -> 3.861 | S54: =SUM(Q54:R54) -> 25.311 | T54: =D54-S54 -> 17.589 | U54: =SUM(AJ53:AQ53) -> 0 | V54: =Y54*I54 -> 2316.6 | W54: =SUM(U54:V54) -> 2316.6 | X54: =I54-W54 -> 23423.4 | Y54: =SUM(AS54) -> 0.09 | AA54: 21.45 | AJ54: 12870 | AS54: 0.09 | AU54: 0.5 | AV54: 0.4
B55: CARRYING channel | C55: =N55*$M$55 -> 44.770408 | D55: =C55*$K$39 -> 49.247449 | E55: l.m | F55: ='Material and Labor Cost'!$D$9 -> 126.5 | G55: ='Material and Labor Cost'!$F$9 -> 70 | H55: =SUM(F55:G55) -> 196.5 | I55: =H55*D55 -> 9677.1237 | M55: =M54/N54 -> 1.5918367 | N55: 28.125 | Q55: =SUM(AA55:AH55) -> 24.623724 | R55: =Y55*D55 -> 4.4322704 | S55: =SUM(Q55:R55) -> 29.055995 | T55: =D55-S55 -> 20.191454 | U55: =SUM(AJ54:AQ54) -> 12870 | V55: =Y55*I55 -> 870.94114 | W55: =SUM(U55:V55) -> 13740.941 | X55: =I55-W55 -> -4063.8174 | Y55: =SUM(AS55) -> 0.09 | AA55: 24.623724 | AJ55: 4838.5619 | AS55: 0.09 | AU55: 0.5 | AV55: 0.4
B56: Metal Furring | C56: =N56*$M$55 -> 72.136735 | D56: =C56*$K$39 -> 79.350408 | E56: l.m | F56: ='Material and Labor Cost'!$D$10 -> 126.5 | G56: ='Material and Labor Cost'!$F$10 -> 70 | H56: =SUM(F56:G56) -> 196.5 | I56: =H56*D56 -> 15592.355 | N56: 45.316667 | Q56: =SUM(AA56:AH56) -> 39.675204 | R56: =Y56*D56 -> 7.1415367 | S56: =SUM(Q56:R56) -> 46.816741 | T56: =D56-S56 -> 32.533667 | U56: =SUM(AJ55:AQ55) -> 4838.5619 | V56: =Y56*I56 -> 1403.312 | W56: =SUM(U56:V56) -> 6241.8738 | X56: =I56-W56 -> 9350.4814 | Y56: =SUM(AS56) -> 0.09 | AA56: 39.675204 | AJ56: 7796.1776 | AS56: 0.09 | AU56: 0.5 | AV56: 0.4
...

Sheet wall
Q10: Unit 6&7 E.M Razon Commercial Building, San Pedro Camuning,
Q11: Mexico, Pampanga, Philippines 2021
Q12: 09951119535 | clients@saikobuilders.com
A14: Project name : | B14: PROPOSED THREE STORY RESIDENCE
A15: Location : | B15: GRAND CENTENIAL HOMES KAWIT CAVITE
A16: Date : | B16: =TODAY() -> 46251
AA17: QUANTITY | AJ17: AMOUNT | AS17: ACCOMPLISHMENT | BB17: PREVIOUS ACCOMPLISHMENT
A18: ITEM NO | B18: Description | C18: QUANTITY | D18: QUANTITY | E18: UNIT | F18: Material Cost Php/unit | G18: Labor and Equipment Cost Php/unit | H18: Total Cost Php/Unit | I18: Total Amount Php | Q18: QUANTITY | U18: AMOUNT | Y18: PERCENTAGE | AA18: BILLING 1 | AB18: BILLING 2 | AC18: BILLING 3 | AD18: BILLING 4 | AE18: BILLING 5 | AF18: BILLING 6 | AG18: BILLING 7 | AH18: BILLING 8 | AJ18: BILLING 1 | AK18: BILLING 2 | AL18: BILLING 3 | AM18: BILLING 4 | AN18: BILLING 5 | AO18: BILLING 6 | AP18: BILLING 7 | AQ18: BILLING 8 | AS18: BILLING 1 | AT18: BILLING 2 | AU18: BILLING 3 | AV18: BILLING 4 | AW18: BILLING 5 | AX18: BILLING 6 | AY18: BILLING 7 | AZ18: BILLING 8 | BB18: BILLING 1 | BC18: BILLING 2 | BD18: BILLING 3 | BE18: BILLING 4 | BF18: BILLING 5 | BG18: BILLING 6 | BH18: BILLING 7 | BI18: BILLING 8
B19: Wall Finish | K19: MARK UP | Q19: PREVIOUS | R19: THIS DATE | S19: TO DATE | T19: BALANCE | U19: PREVIOUS | V19: THIS DATE | W19: TO DATE | X19: BALANCE | Y19: Accomplishment
B20: Ground Floor ( Interior ) | K20: 1.1
B21: FOYER, LIVING, DINING AND KITCHEN | K21: MISS
B22: White Mouldings | C22: 20.3 | D22: =C22*$K$20 -> 22.33 | E22: l.m | F22: ='MATERIAL AND LABOR COST FOR WAL'!$D$7 -> 550 | G22: ='MATERIAL AND LABOR COST FOR WAL'!$F$7 -> 350 | H22: =SUM(F22,G22) -> 900 | I22: =H22*D22 -> 20097 | K22: 0.1 | Q22: =SUM(AA22:AH22) -> 4.466 | R22: =Y22*D22 -> 6.699 | S22: =SUM(Q22:R22) -> 11.165 | T22: =D22-S22 -> 11.165 | U22: =SUM(AJ22:AQ22) -> 4019.4 | V22: =Y22*I22 -> 6029.1 | W22: =SUM(U22:V22) -> 10048.5 | X22: =I22-W22 -> 10048.5 | Y22: =SUM(AS22:AZ22) -> 0.3 | AA22: 4.466 | AJ22: 4019.4 | AS22: 0.3 | BB22: 0.2 | BC22: 0.2
B23: Hidden Door PU Stone Finish Light Beige | C23: 5.8 | D23: =C23*$K$20 -> 6.38 | E23: sqm | F23: ='MATERIAL AND LABOR COST FOR WAL'!$D$8 -> 2150 | G23: ='MATERIAL AND LABOR COST FOR WAL'!$F$8 -> 1200 | H23: =SUM(F23,G23) -> 3350 | I23: =H23*D23 -> 21373 | Q23: =SUM(AA23:AH23) -> 1.276 | R23: =Y23*D23 -> 1.914 | S23: =SUM(Q23:R23) -> 3.19 | T23: =D23-S23 -> 3.19 | U23: =SUM(AJ23:AQ23) -> 4274.6 | V23: =Y23*I23 -> 6411.9 | W23: =SUM(U23:V23) -> 10686.5 | X23: =I23-W23 -> 10686.5 | Y23: =SUM(AS23:AZ23) -> 0.3 | AA23: 1.276 | AJ23: 4274.6 | AS23: 0.3 | BB23: 0.2 | BC23: 0.2
B24: White Fluted | C24: 5.2 | D24: =C24*$K$20 -> 5.72 | E24: sqm | F24: ='MATERIAL AND LABOR COST FOR WAL'!$D$9 -> 880 | G24: ='MATERIAL AND LABOR COST FOR WAL'!$F$9 -> 350 | H24: =SUM(F24,G24) -> 1230 | I24: =H24*D24 -> 7035.6 | Q24: =SUM(AA24:AH24) -> 1.144 | R24: =Y24*D24 -> 1.716 | S24: =SUM(Q24:R24) -> 2.86 | T24: =D24-S24 -> 2.86 | U24: =SUM(AJ24:AQ24) -> 1407.12 | V24: =Y24*I24 -> 2110.68 | W24: =SUM(U24:V24) -> 3517.8 | X24: =I24-W24 -> 3517.8 | Y24: =SUM(AS24:AZ24) -> 0.3 | AA24: 1.144 | AJ24: 1407.12 | AS24: 0.3 | BB24: 0.2 | BC24: 0.2
B25: Laminated Synthetic Marble Finish | C25: 7.4 | D25: =C25*$K$20 -> 8.14 | E25: sqm | F25: ='MATERIAL AND LABOR COST FOR WAL'!$D$10 -> 3300 | G25: ='MATERIAL AND LABOR COST FOR WAL'!$F$10 -> 1650 | H25: =SUM(F25,G25) -> 4950 | I25: =H25*D25 -> 40293 | Q25: =SUM(AA25:AH25) -> 1.628 | R25: =Y25*D25 -> 2.442 | S25: =SUM(Q25:R25) -> 4.07 | T25: =D25-S25 -> 4.07 | U25: =SUM(AJ25:AQ25) -> 8058.6 | V25: =Y25*I25 -> 12087.9 | W25: =SUM(U25:V25) -> 20146.5 | X25: =I25-W25 -> 20146.5 | Y25: =SUM(AS25:AZ25) -> 0.3 | AA25: 1.628 | AJ25: 8058.6 | AS25: 0.3 | BB25: 0.2 | BC25: 0.2
B26: Back Splash Quartz/ White Sintered Stone Terazzo look Finish | C26: 1.1 | D26: =C26*$K$20 -> 1.21 | E26: sqm | F26: ='MATERIAL AND LABOR COST FOR WAL'!$D$11 -> 6600 | G26: ='MATERIAL AND LABOR COST FOR WAL'!$F$11 -> 3300 | H26: =SUM(F26,G26) -> 9900 | I26: =H26*D26 -> 11979 | Q26: =SUM(AA26:AH26) -> 0.242 | R26: =Y26*D26 -> 0.363 | S26: =SUM(Q26:R26) -> 0.605 | T26: =D26-S26 -> 0.605 | U26: =SUM(AJ26:AQ26) -> 2395.8 | V26: =Y26*I26 -> 3593.7 | W26: =SUM(U26:V26) -> 5989.5 | X26: =I26-W26 -> 5989.5 | Y26: =SUM(AS26:AZ26) -> 0.3 | AA26: 0.242 | AJ26: 2395.8 | AS26: 0.3 | BB26: 0.2 | BC26: 0.2
B27: Semi Gloss | C27: 42.3 | D27: =C27*$K$20 -> 46.53 | E27: sqm | F27: ='MATERIAL AND LABOR COST FOR WAL'!$D$12 -> 350 | G27: ='MATERIAL AND LABOR COST FOR WAL'!$F$12 -> 350 | H27: =SUM(F27,G27) -> 700 | I27: =H27*D27 -> 32571 | Q27: =SUM(AA27:AH27) -> 9.306 | R27: =Y27*D27 -> 13.959 | S27: =SUM(Q27:R27) -> 23.265 | T27: =D27-S27 -> 23.265 | U27: =SUM(AJ27:AQ27) -> 6514.2 | V27: =Y27*I27 -> 9771.3 | W27: =SUM(U27:V27) -> 16285.5 | X27: =I27-W27 -> 16285.5 | Y27: =SUM(AS27:AZ27) -> 0.3 | AA27: 9.306 | AJ27: 6514.2 | AS27: 0.3 | BB27: 0.2 | BC27: 0.2
B28: Wood Laminated Finish | C28: 1.6 | D28: =C28*$K$20 -> 1.76 | E28: sqm | F28: ='MATERIAL AND LABOR COST FOR WAL'!$D$13 -> 825 | G28: ='MATERIAL AND LABOR COST FOR WAL'!$F$13 -> 350 | H28: =SUM(F28,G28) -> 1175 | I28: =H28*D28 -> 2068 | Q28: =SUM(AA28:AH28) -> 0.352 | R28: =Y28*D28 -> 0.528 | S28: =SUM(Q28:R28) -> 0.88 | T28: =D28-S28 -> 0.88 | U28: =SUM(AJ28:AQ28) -> 413.6 | V28: =Y28*I28 -> 620.4 | W28: =SUM(U28:V28) -> 1034 | X28: =I28-W28 -> 1034 | Y28: =SUM(AS28:AZ28) -> 0.3 | AA28: 0.352 | AJ28: 413.6 | AS28: 0.3 | BB28: 0.2 | BC28: 0.2
B29: Beveled Clear Mirror 10mm THK | C29: 2.5 | D29: =C29*$K$20 -> 2.75 | E29: sqm | F29: ='MATERIAL AND LABOR COST FOR WAL'!$D$14 -> 1375 | G29: ='MATERIAL AND LABOR COST FOR WAL'!$F$14 -> 700 | H29: =SUM(F29,G29) -> 2075 | I29: =D29*H29 -> 5706.25 | Q29: =SUM(AA29:AH29) -> 0.55 | R29: =Y29*D29 -> 0.825 | S29: =SUM(Q29:R29) -> 1.375 | T29: =D29-S29 -> 1.375 | U29: =SUM(AJ29:AQ29) -> 1141.25 | V29: =Y29*I29 -> 1711.875 | W29: =SUM(U29:V29) -> 2853.125 | X29: =I29-W29 -> 2853.125 | Y29: =SUM(AS29:AZ29) -> 0.3 | AA29: 0.55 | AJ29: 1141.25 | AS29: 0.3 | BB29: 0.2 | BC29: 0.2
B31: OFFICE | F31: ='MATERIAL AND LABOR COST FOR WAL'!D15 -> 0
B32: Biege Textured Wallpaper Finish | C32: 15 | D32: =C32*$K$20 -> 16.5 | E32: sqm | F32: ='MATERIAL AND LABOR COST FOR WAL'!$D$16 -> 825 | G32: ='MATERIAL AND LABOR COST FOR WAL'!$F$16 -> 350 | H32: =SUM(F32,G32) -> 1175 | I32: =H32*D32 -> 19387.5 | Q32: =SUM(AA32:AH32) -> 1.65 | R32: =Y32*D32 -> 4.95 | S32: =SUM(Q32:R32) -> 6.6 | T32: =D32-S32 -> 9.9 | U32: =SUM(AJ32:AQ32) -> 1938.75 | V32: =Y32*I32 -> 5816.25 | W32: =SUM(U32:V32) -> 7755 | X32: =I32-W32 -> 11632.5 | Y32: =SUM(AS32:AZ32) -> 0.3 | AA32: 1.65 | AJ32: 1938.75 | AS32: 0.3 | BB32: 0.1 | BC32: 0.1
B33: PU Stone Textured Light Biege Finish | C33: 3.8 | D33: =C33*$K$20 -> 4.18 | E33: sqm | F33: ='MATERIAL AND LABOR COST FOR WAL'!$D$17 -> 2150 | G33: ='MATERIAL AND LABOR COST FOR WAL'!$F$17 -> 1200 | H33: =SUM(F33,G33) -> 3350 | I33: =H33*D33 -> 14003 | Q33: =SUM(AA33:AH33) -> 0.418 | R33: =Y33*D33 -> 1.254 | S33: =SUM(Q33:R33) -> 1.672 | T33: =D33-S33 -> 2.508 | U33: =SUM(AJ33:AQ33) -> 1400.3 | V33: =Y33*I33 -> 4200.9 | W33: =SUM(U33:V33) -> 5601.2 | X33: =I33-W33 -> 8401.8 | Y33: =SUM(AS33:AZ33) -> 0.3 | AA33: 0.418 | AJ33: 1400.3 | AS33: 0.3 | BB33: 0.1 | BC33: 0.1
B34: 18 mm THK MDF Plywood Wall Cladding in Wood Finish w/ warm strip light | C34: 3.7 | D34: =C34*$K$20 -> 4.07 | E34: sqm | F34: ='MATERIAL AND LABOR COST FOR WAL'!$D$18 -> 1375 | G34: ='MATERIAL AND LABOR COST FOR WAL'!$F$18 -> 700 | H34: =SUM(F34,G34) -> 2075 | I34: =H34*D34 -> 8445.25 | Q34: =SUM(AA34:AH34) -> 0.407 | R34: =Y34*D34 -> 1.221 | S34: =SUM(Q34:R34) -> 1.628 | T34: =D34-S34 -> 2.442 | U34: =SUM(AJ34:AQ34) -> 844.525 | V34: =Y34*I34 -> 2533.575 | W34: =SUM(U34:V34) -> 3378.1 | X34: =I34-W34 -> 5067.15 | Y34: =SUM(AS34:AZ34) -> 0.3 | AA34: 0.407 | AJ34: 844.525 | AS34: 0.3 | BB34: 0.1 | BC34: 0.1
B35: Semi Gloss Off White | C35: 7.1 | D35: =C35*$K$20 -> 7.81 | E35: sqm | F35: ='MATERIAL AND LABOR COST FOR WAL'!$D$19 -> 350 | G35: ='MATERIAL AND LABOR COST FOR WAL'!$F$19 -> 350 | H35: =SUM(F35,G35) -> 700 | I35: =H35*D35 -> 5467 | Q35: =SUM(AA35:AH35) -> 0.781 | R35: =Y35*D35 -> 2.343 | S35: =SUM(Q35:R35) -> 3.124 | T35: =D35-S35 -> 4.686 | U35: =SUM(AJ35:AQ35) -> 546.7 | V35: =Y35*I35 -> 1640.1 | W35: =SUM(U35:V35) -> 2186.8 | X35: =I35-W35 -> 3280.2 | Y35: =SUM(AS35:AZ35) -> 0.3 | AA35: 0.781 | AJ35: 546.7 | AS35: 0.3 | BB35: 0.1 | BC35: 0.1
B37: POWDER ROOM
B38: 60X120 Gray Marble Tiles In High Gloss Finish | C38: 22 | D38: =C38*$K$20 -> 24.2 | E38: sqm | F38: ='MATERIAL AND LABOR COST FOR WAL'!$D$20 -> 550 | G38: ='MATERIAL AND LABOR COST FOR WAL'!$F$20 -> 350 | H38: =SUM(F38,G38) -> 900 | I38: =D38*H38 -> 21780 | Q38: =SUM(AA38:AH38) -> 2.42 | R38: =Y38*D38 -> 14.52 | S38: =SUM(Q38:R38) -> 16.94 | T38: =D38-S38 -> 7.26 | U38: =SUM(AJ38:AQ38) -> 2178 | V38: =Y38*I38 -> 13068 | W38: =SUM(U38:V38) -> 15246 | X38: =I38-W38 -> 6534 | Y38: =SUM(AS38:AZ38) -> 0.6 | AA38: 2.42 | AJ38: 2178 | AS38: 0.6 | BB38: 0.1 | BC38: 0.1
B39: Miscellaneous and other consumables | D39: 1 | E39: lot | I39: =SUM(I22:I38)*$K$22 -> 21020.56 | Q39: =SUM(AA39:AH39) -> 0.1 | R39: =Y39*D39 -> 0.6 | S39: =SUM(Q39:R39) -> 0.7 | T39: =D39-S39 -> 0.3 | U39: =SUM(AJ39:AQ39) -> 2102.056 | V39: =Y39*I39 -> 12612.336 | W39: =SUM(U39:V39) -> 14714.392 | X39: =I39-W39 -> 6306.168 | Y39: =SUM(AS39:AZ39) -> 0.6 | AA39: 0.1 | AJ39: 2102.056 | AS39: 0.6 | BB39: 0.1 | BC39: 0.1
B40: Sub-Total for Ground Floor (Interior) | I40: =SUM(I22:I39) -> 231226.16 | Q40: =SUM(Q22:Q39) -> 24.74 | R40: =SUM(R22:R39) -> 53.334 | S40: =SUM(S22:S39) -> 78.074 | T40: =SUM(T22:T39) -> 74.506 | U40: =SUM(U22:U39) -> 37234.901 | V40: =SUM(V22:V39) -> 82208.016 | W40: =SUM(W22:W39) -> 119442.92 | X40: =SUM(X22:X39) -> 111783.24 | Y40: =SUM(Y22:Y39)/COUNT(Y22:Y39) -> 0.34285714 | AA40: 24.74 | AJ40: 37234.901 | BB40: =SUM(BB22:BB39)/COUNT(BB22:BB39) -> 0.15714286 | BC40: =SUM(BC22:BC39)/COUNT(BC22:BC39) -> 0.15714286
B42: Ground Floor ( Exterior )
B43: Exposed Aggregate Concrete Cladding | C43: 1.6 | D43: =C43*$K$20 -> 1.76 | E43: sqm | F43: ='MATERIAL AND LABOR COST FOR WAL'!$D$22 -> 350 | G43: ='MATERIAL AND LABOR COST FOR WAL'!$F$22 -> 350 | H43: =SUM(F43,G43) -> 700 | I43: =H43*D43 -> 1232 | Q43: =SUM(AA43:AH43) -> 0.176 | R43: =Y43*D43 -> 0.176 | S43: =SUM(Q43:R43) -> 0.352 | T43: =D43-S43 -> 1.408 | U43: =SUM(AJ43:AQ43) -> 123.2 | V43: =Y43*I43 -> 123.2 | W43: =SUM(U43:V43) -> 246.4 | X43: =I43-W43 -> 985.6 | Y43: =SUM(AS43:AZ43) -> 0.1 | AA43: 0.176 | AJ43: 123.2 | AS43: 0.1 | BB43: 0.1 | BC43: 0.1
B44: Wall Flashing ( Dark Gray ) | C44: 46.4 | D44: =C44*$K$20 -> 51.04 | E44: Im | F44: ='MATERIAL AND LABOR COST FOR WAL'!$D$23 -> 550 | G44: ='MATERIAL AND LABOR COST FOR WAL'!$F$23 -> 350 | H44: =SUM(F44,G44) -> 900 | I44: =H44*D44 -> 45936 | Q44: =SUM(AA44:AH44) -> 5.104 | R44: =Y44*D44 -> 28.072 | S44: =SUM(Q44:R44) -> 33.176 | T44: =D44-S44 -> 17.864 | U44: =SUM(AJ44:AQ44) -> 4593.6 | V44: =Y44*I44 -> 25264.8 | W44: =SUM(U44:V44) -> 29858.4 | X44: =I44-W44 -> 16077.6 | Y44: =SUM(AS44:AZ44) -> 0.55 | AA44: 5.104 | AJ44: 4593.6 | AS44: 0.55 | BB44: 0.1 | BC44: 0.1
B45: Wall Piaint Finish ( Off White ) | C45: 69.82 | D45: =C45*$K$20 -> 76.802 | E45: sqm | F45: ='MATERIAL AND LABOR COST FOR WAL'!$D$24 -> 350 | G45: ='MATERIAL AND LABOR COST FOR WAL'!$F$24 -> 350 | H45: =SUM(F45,G45) -> 700 | I45: =H45*D45 -> 53761.4 | Q45: =SUM(AA45:AH45) -> 7.6802 | R45: =Y45*D45 -> 46.0812 | S45: =SUM(Q45:R45) -> 53.7614 | T45: =D45-S45 -> 23.0406 | U45: =SUM(AJ45:AQ45) -> 5376.14 | V45: =Y45*I45 -> 32256.84 | W45: =SUM(U45:V45) -> 37632.98 | X45: =I45-W45 -> 16128.42 | Y45: =SUM(AS45:AZ45) -> 0.6 | AA45: 7.6802 | AJ45: 5376.14 | AS45: 0.6 | BB45: 0.1 | BC45: 0.1
B46: Natural Limestone Tiles Texture Running Ashlar Pattern | C46: 14.8 | D46: =C46*$K$20 -> 16.28 | E46: sqm | F46: ='MATERIAL AND LABOR COST FOR WAL'!$D$25 -> 950 | G46: ='MATERIAL AND LABOR COST FOR WAL'!$F$25 -> 350 | H46: =SUM(F46,G46) -> 1300 | I46: =H46*D46 -> 21164 | Q46: =SUM(AA46:AH46) -> 1.628 | R46: =Y46*D46 -> 6.512 | S46: =SUM(Q46:R46) -> 8.14 | T46: =D46-S46 -> 8.14 | U46: =SUM(AJ46:AQ46) -> 2116.4 | V46: =Y46*I46 -> 8465.6 | W46: =SUM(U46:V46) -> 10582 | X46: =I46-W46 -> 10582 | Y46: =SUM(AS46:AZ46) -> 0.4 | AA46: 1.628 | AJ46: 2116.4 | AS46: 0.4 | BB46: 0.1 | BC46: 0.3
B47: Wall Piaint Finish ( Dark Gray ) | C47: 19.1 | D47: =C47*$K$20 -> 21.01 | E47: sqm | F47: ='MATERIAL AND LABOR COST FOR WAL'!$D$26 -> 350 | G47: ='MATERIAL AND LABOR COST FOR WAL'!$F$26 -> 350 | H47: =SUM(F47,G47) -> 700 | I47: =D47*H47 -> 14707 | Q47: =SUM(AA47:AH47) -> 2.101 | R47: =Y47*D47 -> 12.606 | S47: =SUM(Q47:R47) -> 14.707 | T47: =D47-S47 -> 6.303 | U47: =SUM(AJ47:AQ47) -> 1470.7 | V47: =Y47*I47 -> 8824.2 | W47: =SUM(U47:V47) -> 10294.9 | X47: =I47-W47 -> 4412.1 | Y47: =SUM(AS47:AZ47) -> 0.6 | AA47: 2.101 | AJ47: 1470.7 | AS47: 0.6 | BB47: 0.1 | BC47: 0.1
B48: Miscellaneous and other consumables | D48: 1 | E48: lot | I48: =SUM(I43:I47)*$K$22 -> 13680.04 | Q48: =SUM(AA48:AH48) -> 0.1 | R48: =Y48*D48 -> 0.5 | S48: =SUM(Q48:R48) -> 0.6 | T48: =D48-S48 -> 0.4 | U48: =SUM(AJ48:AQ48) -> 1368.004 | V48: =Y48*I48 -> 6840.02 | W48: =SUM(U48:V48) -> 8208.024 | X48: =I48-W48 -> 5472.016 | Y48: =SUM(AS48:AZ48) -> 0.5 | AA48: 0.1 | AJ48: 1368.004 | AS48: 0.5 | BB48: 0.1 | BC48: 0.15
B49: Sub-total for Ground Floor (Exterior) | I49: =SUM(I43:I48) -> 150480.44 | Q49: =SUM(Q43:Q48) -> 16.7892 | R49: =SUM(R43:R48) -> 93.9472 | S49: =SUM(S43:S48) -> 110.7364 | T49: =SUM(T43:T48) -> 57.1556 | U49: =SUM(U43:U48) -> 15048.044 | V49: =SUM(V43:V48) -> 81774.66 | W49: =SUM(W43:W48) -> 96822.704 | X49: =SUM(X43:X48) -> 53657.736 | Y49: =SUM(Y43:Y48)/COUNT(Y43:Y48) -> 0.45833333 | AA49: 16.7892 | AJ49: 15048.044 | BB49: =SUM(BB43:BB48)/COUNT(BB43:BB48) -> 0.1 | BC49: =SUM(BC43:BC48)/COUNT(BC43:BC48) -> 0.14166667
B51: Second Floor ( Interior )
B52: BEDROOM 1
B53: Wall in Light Biege Semi-Gloss Painted Finish | C53: 39 | D53: =C53*$K$20 -> 42.9 | E53: sqm | F53: ='MATERIAL AND LABOR COST FOR WAL'!$D$29 -> 350 | G53: ='MATERIAL AND LABOR COST FOR WAL'!$F$29 -> 350 | H53: =SUM(F53,G53) -> 700 | I53: =H53*D53 -> 30030 | Q53: =SUM(AA53:AH53) -> 4.29 | R53: =Y53*D53 -> 17.16 | S53: =SUM(Q53:R53) -> 21.45 | T53: =D53-S53 -> 21.45 | U53: =SUM(AJ53:AQ53) -> 3003 | V53: =Y53*I53 -> 12012 | W53: =SUM(U53:V53) -> 15015 | X53: =I53-W53 -> 15015 | Y53: =SUM(AS53:AZ53) -> 0.4 | AA53: 4.29 | AJ53: 3003 | AS53: 0.4 | BB53: 0.1 | BC53: 0.2
B54: Wall in Light Biege Semi-Gloss Painted Finish with mouldings | C54: 22.6 | D54: =C54*$K$20 -> 24.86 | E54: Im | F54: ='MATERIAL AND LABOR COST FOR WAL'!$D$30 -> 550 | G54: ='MATERIAL AND LABOR COST FOR WAL'!$F$30 -> 350 | H54: =SUM(F54,G54) -> 900 | I54: =H54*D54 -> 22374 | Q54: =SUM(AA54:AH54) -> 2.486 | R54: =Y54*D54 -> 9.944 | S54: =SUM(Q54:R54) -> 12.43 | T54: =D54-S54 -> 12.43 | U54: =SUM(AJ54:AQ54) -> 2237.4 | V54: =Y54*I54 -> 8949.6 | W54: =SUM(U54:V54) -> 11187 | X54: =I54-W54 -> 11187 | Y54: =SUM(AS54:AZ54) -> 0.4 | AA54: 2.486 | AJ54: 2237.4 | AS54: 0.4 | BB54: 0.1 | BC54: 0.2
...

Sheet CABINETS
A13: Project name : | B13: PROPOSED THREE STORY RESIDENCE
A14: Location : | B14: GRAND CENTENIAL HOMES KAWIT CAVITE
A15: Date : | B15: =TODAY() -> 46251
AI16: QUANTITY | AR16: AMOUNT | BA16: ACCOMPLISHMENT | BC16: PREVIOUS ACCOMPLISHMENT
A17: ITEM NO | B17: Description | C17: QUANTITY | D17: QUANTITY | E17: UNIT | F17: Material Cost Php/unit | G17: Labor and Equipment Cost Php/unit | H17: Total Cost Php/Unit | I17: Total Amount Php | Y17: QUANTITY | AC17: AMOUNT | AG17: PERCENTAGE | AI17: BILLING 1 | AJ17: BILLING 2 | AK17: BILLING 3 | AL17: BILLING 4 | AM17: BILLING 5 | AN17: BILLING 6 | AO17: BILLING 7 | AP17: BILLING 8 | AR17: BILLING 1 | AS17: BILLING 2 | AT17: BILLING 3 | AU17: BILLING 4 | AV17: BILLING 5 | AW17: BILLING 6 | AX17: BILLING 7 | AY17: BILLING 8 | BA17: BILLING | BC17: BILLING 1 | BD17: BILLING 2 | BE17: BILLING 3 | BF17: BILLING 4 | BG17: BILLING 5 | BH17: BILLING 6 | BI17: BILLING 7 | BJ17: BILLING 8
B18: Cabinets | Y18: PREVIOUS | Z18: THIS DATE | AA18: TO DATE | AB18: BALANCE | AC18: PREVIOUS | AD18: THIS DATE | AE18: TO DATE | AF18: BALANCE | AG18: Accomplishment
B19: GROUND FLOOR
B20: LIving Area ( Tv rack with Cabinets )
B21: UV Board Marble | C21: 6.7 | D21: =C21*$L$23 -> 7.37 | E21: sq.m | F21: ='Material and Labor Cost'!$D$20 -> 555 | G21: ='Material and Labor Cost'!$F$20 -> 300 | H21: =SUM(F21:G21) -> 855 | I21: =H21*D21 -> 6301.35 | Y21: =SUM(AI21:AP21) -> 0 | Z21: =D21*AG21 -> 2.211 | AA21: =SUM(Y21:Z21) -> 2.211 | AB21: =D21-AA21 -> 5.159 | AC21: =SUM(AR20:AY20) -> 0 | AD21: =AG21*I21 -> 1890.405 | AE21: =SUM(AC21:AD21) -> 1890.405 | AF21: =I21-AE21 -> 4410.945 | AG21: =BA21 -> 0.3 | AI21: 0 | BA21: 0.3 | BC21: =SUM(BS20:BZ20) -> 0 | BD21: =SUM(BN20:BT20) -> 0 | BE21: =SUM(BU20:CB20) -> 0 | BF21: =SUM(BV20:CC20) -> 0 | BG21: =SUM(BW20:CD20) -> 0 | BH21: =SUM(BX20:CE20) -> 0 | BI21: =SUM(BY20:CF20) -> 0 | BJ21: =SUM(BZ20:CG20) -> 0
B22: 3/4'' Marine Plywood | C22: 45.74 | D22: =C22*$L$23 -> 50.314 | E22: sq.m | F22: ='Material and Labor Cost'!$D$21 -> 576 | G22: ='Material and Labor Cost'!$F$21 -> 300 | H22: =SUM(F22:G22) -> 876 | I22: =H22*D22 -> 44075.064 | L22: Multiplier Mark up | Y22: =SUM(AI22:AP22) -> 0 | Z22: =D22*AG22 -> 15.0942 | AA22: =SUM(Y22:Z22) -> 15.0942 | AB22: =D22-AA22 -> 35.2198 | AC22: =SUM(AR21:AY21) -> 0 | AD22: =AG22*I22 -> 13222.519 | AE22: =SUM(AC22:AD22) -> 13222.519 | AF22: =I22-AE22 -> 30852.545 | AG22: =BA22 -> 0.3 | AI22: 0 | BA22: 0.3 | BC22: =SUM(BS21:BZ21) -> 0 | BD22: =SUM(BN21:BT21) -> 0 | BE22: =SUM(BU21:CB21) -> 0 | BF22: =SUM(BV21:CC21) -> 0 | BG22: =SUM(BW21:CD21) -> 0 | BH22: =SUM(BX21:CE21) -> 0 | BI22: =SUM(BY21:CF21) -> 0 | BJ22: =SUM(BZ21:CG21) -> 0
B23: Pvc Fluted Panels | C23: 5 | D23: =C23*$L$23 -> 5.5 | E23: sq.m | F23: ='Material and Labor Cost'!$D$22 -> 880 | G23: ='Material and Labor Cost'!$F$22 -> 450 | H23: =SUM(F23:G23) -> 1330 | I23: =H23*D23 -> 7315 | L23: 1.1 | Y23: =SUM(AI23:AP23) -> 0 | Z23: =D23*AG23 -> 0 | AA23: =SUM(Y23:Z23) -> 0 | AB23: =D23-AA23 -> 5.5 | AC23: =SUM(AR22:AY22) -> 0 | AD23: =AG23*I23 -> 0 | AE23: =SUM(AC23:AD23) -> 0 | AF23: =I23-AE23 -> 7315 | AG23: =BA23 -> 0 | AI23: 0 | BA23: =SUM(BK22:BQ22) -> 0 | BC23: =SUM(BS22:BZ22) -> 0 | BD23: =SUM(BN22:BT22) -> 0 | BE23: =SUM(BU22:CB22) -> 0 | BF23: =SUM(BV22:CC22) -> 0 | BG23: =SUM(BW22:CD22) -> 0 | BH23: =SUM(BX22:CE22) -> 0 | BI23: =SUM(BY22:CF22) -> 0 | BJ23: =SUM(BZ22:CG22) -> 0
B24: 1/2'' Backing Marine plywood | C24: 12 | D24: =C24*$L$23 -> 13.2 | E24: sq.m | F24: ='Material and Labor Cost'!$D$23 -> 330 | G24: ='Material and Labor Cost'!$F$23 -> 165 | H24: =SUM(F24:G24) -> 495 | I24: =H24*D24 -> 6534 | Y24: =SUM(AI24:AP24) -> 0 | Z24: =D24*AG24 -> 0 | AA24: =SUM(Y24:Z24) -> 0 | AB24: =D24-AA24 -> 13.2 | AC24: =SUM(AR23:AY23) -> 0 | AD24: =AG24*I24 -> 0 | AE24: =SUM(AC24:AD24) -> 0 | AF24: =I24-AE24 -> 6534 | AG24: =BA24 -> 0 | AI24: 0 | BA24: =SUM(BK23:BQ23) -> 0 | BC24: =SUM(BS23:BZ23) -> 0 | BD24: =SUM(BN23:BT23) -> 0 | BE24: =SUM(BU23:CB23) -> 0 | BF24: =SUM(BV23:CC23) -> 0 | BG24: =SUM(BW23:CD23) -> 0 | BH24: =SUM(BX23:CE23) -> 0 | BI24: =SUM(BY23:CF23) -> 0 | BJ24: =SUM(BZ23:CG23) -> 0
B25: Warm Strip Lights | C25: 2.31 | D25: =C25*$L$23 -> 2.541 | E25: l.m | F25: ='Material and Labor Cost'!$D$24 -> 220 | G25: ='Material and Labor Cost'!$F$24 -> 110 | H25: =SUM(F25:G25) -> 330 | I25: =H25*D25 -> 838.53 | Y25: =SUM(AI25:AP25) -> 0 | Z25: =D25*AG25 -> 0 | AA25: =SUM(Y25:Z25) -> 0 | AB25: =D25-AA25 -> 2.541 | AC25: =SUM(AR24:AY24) -> 0 | AD25: =AG25*I25 -> 0 | AE25: =SUM(AC25:AD25) -> 0 | AF25: =I25-AE25 -> 838.53 | AG25: =BA25 -> 0 | AI25: 0 | BA25: =SUM(BK24:BQ24) -> 0 | BC25: =SUM(BS24:BZ24) -> 0 | BD25: =SUM(BN24:BT24) -> 0 | BE25: =SUM(BU24:CB24) -> 0 | BF25: =SUM(BV24:CC24) -> 0 | BG25: =SUM(BW24:CD24) -> 0 | BH25: =SUM(BX24:CE24) -> 0 | BI25: =SUM(BY24:CF24) -> 0 | BJ25: =SUM(BZ24:CG24) -> 0
B26: Paint Finish | C26: 34.04 | D26: =C26*$L$23 -> 37.444 | E26: sq.m | F26: ='Material and Labor Cost'!$D$25 -> 555 | G26: ='Material and Labor Cost'!$F$25 -> 275 | H26: =SUM(F26:G26) -> 830 | I26: =H26*D26 -> 31078.52 | L26: Miscellaneous | Y26: =SUM(AI26:AP26) -> 0 | Z26: =D26*AG26 -> 0 | AA26: =SUM(Y26:Z26) -> 0 | AB26: =D26-AA26 -> 37.444 | AC26: =SUM(AR25:AY25) -> 0 | AD26: =AG26*I26 -> 0 | AE26: =SUM(AC26:AD26) -> 0 | AF26: =I26-AE26 -> 31078.52 | AG26: =BA26 -> 0 | AI26: 0 | BA26: =SUM(BK25:BQ25) -> 0 | BC26: =SUM(BS25:BZ25) -> 0 | BD26: =SUM(BN25:BT25) -> 0 | BE26: =SUM(BU25:CB25) -> 0 | BF26: =SUM(BV25:CC25) -> 0 | BG26: =SUM(BW25:CD25) -> 0 | BH26: =SUM(BX25:CE25) -> 0 | BI26: =SUM(BY25:CF25) -> 0 | BJ26: =SUM(BZ25:CG25) -> 0
B27: Miscellaneous and other Consumables | D27: 1 | E27: lot | I27: =SUM(I21:I26)*$L$27 -> 11537.096 | L27: 0.12 | Y27: =SUM(AI27:AP27) -> 0 | Z27: =D27*AG27 -> 0 | AA27: =SUM(Y27:Z27) -> 0 | AB27: =D27-AA27 -> 1 | AC27: =SUM(AR26:AY26) -> 0 | AD27: =AG27*I27 -> 0 | AE27: =SUM(AC27:AD27) -> 0 | AF27: =I27-AE27 -> 11537.096 | AG27: =BA27 -> 0 | AI27: 0 | BA27: =SUM(BK26:BQ26) -> 0 | BC27: =SUM(BS26:BZ26) -> 0 | BD27: =SUM(BN26:BT26) -> 0 | BE27: =SUM(BU26:CB26) -> 0 | BF27: =SUM(BV26:CC26) -> 0 | BG27: =SUM(BW26:CD26) -> 0 | BH27: =SUM(BX26:CE26) -> 0 | BI27: =SUM(BY26:CF26) -> 0 | BJ27: =SUM(BZ26:CG26) -> 0
B28: LIving Area ( Tv rack with Cabinets ) Sub-total: | I28: =SUM(I21:I27) -> 107679.56 | L28: 0.8 | Y28: =SUM(Y21:Y27) -> 0 | Z28: =SUM(Z21:Z27) -> 17.3052 | AA28: =SUM(AA21:AA27) -> 17.3052 | AB28: =SUM(AB21:AB27) -> 100.0638 | AC28: =SUM(AC21:AC27) -> 0 | AD28: =SUM(AD21:AD27) -> 15112.924 | AE28: =SUM(AE21:AE27) -> 15112.924 | AF28: =SUM(AF21:AF27) -> 92566.635 | AG28: =BA28 -> 0.085714286 | AI28: 0 | BA28: =SUM(BA21:BA27)/COUNT(BA21:BA27) -> 0.085714286 | BC28: =SUM(BC21:BC27)/COUNT(BC21:BC27) -> 0 | BD28: =SUM(BD21:BD27)/COUNT(BD21:BD27) -> 0 | BE28: =SUM(BE21:BE27)/COUNT(BE21:BE27) -> 0 | BF28: =SUM(BF21:BF27)/COUNT(BF21:BF27) -> 0 | BG28: =SUM(BG21:BG27)/COUNT(BG21:BG27) -> 0 | BH28: =SUM(BH21:BH27)/COUNT(BH21:BH27) -> 0 | BI28: =SUM(BI21:BI27)/COUNT(BI21:BI27) -> 0 | BJ28: =SUM(BJ21:BJ27)/COUNT(BJ21:BJ27) -> 0
B29: LIving Area ( Storage Cabinets ) | AG29: =BA29 -> 0
B30: 3/4'' Marine Plywood | C30: 7.9 | D30: =C30*$L$23 -> 8.69 | E30: sq.m | F30: ='Material and Labor Cost'!$D$21 -> 576 | G30: ='Material and Labor Cost'!$F$21 -> 300 | H30: =SUM(F30:G30) -> 876 | I30: =H30*D30 -> 7612.44 | Y30: =SUM(AI30:AP30) -> 0 | Z30: =D30*AG30 -> 2.607 | AA30: =SUM(Y30:Z30) -> 2.607 | AB30: =D30-AA30 -> 6.083 | AC30: =SUM(AR29:AY29) -> 0 | AD30: =AG30*I30 -> 2283.732 | AE30: =SUM(AC30:AD30) -> 2283.732 | AF30: =I30-AE30 -> 5328.708 | AG30: =BA30 -> 0.3 | AI30: 0 | BA30: 0.3 | BC30: =SUM(BS29:BZ29) -> 0 | BD30: =SUM(BN29:BT29) -> 0 | BE30: =SUM(BU29:CB29) -> 0 | BF30: =SUM(BV29:CC29) -> 0 | BG30: =SUM(BW29:CD29) -> 0 | BH30: =SUM(BX29:CE29) -> 0 | BI30: =SUM(BY29:CF29) -> 0 | BJ30: =SUM(BZ29:CG29) -> 0
B31: 1/2'' Backing Marine plywood | C31: 2.1 | D31: =C31*$L$23 -> 2.31 | E31: sq.m | F31: ='Material and Labor Cost'!$D$23 -> 330 | G31: ='Material and Labor Cost'!$F$23 -> 165 | H31: =SUM(F31:G31) -> 495 | I31: =H31*D31 -> 1143.45 | Y31: =SUM(AI31:AP31) -> 0 | Z31: =D31*AG31 -> 0.693 | AA31: =SUM(Y31:Z31) -> 0.693 | AB31: =D31-AA31 -> 1.617 | AC31: =SUM(AR30:AY30) -> 0 | AD31: =AG31*I31 -> 343.035 | AE31: =SUM(AC31:AD31) -> 343.035 | AF31: =I31-AE31 -> 800.415 | AG31: =BA31 -> 0.3 | AI31: 0 | BA31: 0.3 | BC31: =SUM(BS30:BZ30) -> 0 | BD31: =SUM(BN30:BT30) -> 0 | BE31: =SUM(BU30:CB30) -> 0 | BF31: =SUM(BV30:CC30) -> 0 | BG31: =SUM(BW30:CD30) -> 0 | BH31: =SUM(BX30:CE30) -> 0 | BI31: =SUM(BY30:CF30) -> 0 | BJ31: =SUM(BZ30:CG30) -> 0
B32: Paint Finish | C32: 3.94 | D32: =C32*$L$23 -> 4.334 | E32: sq.m | F32: ='Material and Labor Cost'!$D$25 -> 555 | G32: ='Material and Labor Cost'!$F$25 -> 275 | H32: =SUM(F32:G32) -> 830 | I32: =H32*D32 -> 3597.22 | Y32: =SUM(AI32:AP32) -> 0 | Z32: =D32*AG32 -> 0 | AA32: =SUM(Y32:Z32) -> 0 | AB32: =D32-AA32 -> 4.334 | AC32: =SUM(AR31:AY31) -> 0 | AD32: =AG32*I32 -> 0 | AE32: =SUM(AC32:AD32) -> 0 | AF32: =I32-AE32 -> 3597.22 | AG32: =BA32 -> 0 | AI32: 0 | BA32: =SUM(BK31:BQ31) -> 0 | BC32: =SUM(BS31:BZ31) -> 0 | BD32: =SUM(BN31:BT31) -> 0 | BE32: =SUM(BU31:CB31) -> 0 | BF32: =SUM(BV31:CC31) -> 0 | BG32: =SUM(BW31:CD31) -> 0 | BH32: =SUM(BX31:CE31) -> 0 | BI32: =SUM(BY31:CF31) -> 0 | BJ32: =SUM(BZ31:CG31) -> 0
B33: Ducco Finish | C33: 3.96 | D33: =C33*$L$23 -> 4.356 | E33: sq.m | F33: ='Material and Labor Cost'!$D$26 -> 555 | G33: ='Material and Labor Cost'!$F$26 -> 275 | H33: =SUM(F33:G33) -> 830 | I33: =H33*D33 -> 3615.48 | Y33: =SUM(AI33:AP33) -> 0 | Z33: =D33*AG33 -> 0 | AA33: =SUM(Y33:Z33) -> 0 | AB33: =D33-AA33 -> 4.356 | AC33: =SUM(AR32:AY32) -> 0 | AD33: =AG33*I33 -> 0 | AE33: =SUM(AC33:AD33) -> 0 | AF33: =I33-AE33 -> 3615.48 | AG33: =BA33 -> 0 | AI33: 0 | BA33: =SUM(BK32:BQ32) -> 0 | BC33: =SUM(BS32:BZ32) -> 0 | BD33: =SUM(BN32:BT32) -> 0 | BE33: =SUM(BU32:CB32) -> 0 | BF33: =SUM(BV32:CC32) -> 0 | BG33: =SUM(BW32:CD32) -> 0 | BH33: =SUM(BX32:CE32) -> 0 | BI33: =SUM(BY32:CF32) -> 0 | BJ33: =SUM(BZ32:CG32) -> 0
B34: Miscellaneous and other Consumables | D34: 1 | E34: lot | I34: =SUM(I30:I33)*L72 -> 7984.295 | Y34: =SUM(AI34:AP34) -> 0 | Z34: =D34*AG34 -> 0 | AA34: =SUM(Y34:Z34) -> 0 | AB34: =D34-AA34 -> 1 | AC34: =SUM(AR33:AY33) -> 0 | AD34: =AG34*I34 -> 0 | AE34: =SUM(AC34:AD34) -> 0 | AF34: =I34-AE34 -> 7984.295 | AG34: =BA34 -> 0 | AI34: 0 | BA34: =SUM(BK33:BQ33) -> 0 | BC34: =SUM(BS33:BZ33) -> 0 | BD34: =SUM(BN33:BT33) -> 0 | BE34: =SUM(BU33:CB33) -> 0 | BF34: =SUM(BV33:CC33) -> 0 | BG34: =SUM(BW33:CD33) -> 0 | BH34: =SUM(BX33:CE33) -> 0 | BI34: =SUM(BY33:CF33) -> 0 | BJ34: =SUM(BZ33:CG33) -> 0
B35: LIving Area ( Storage Cabinets ) Sub-total: | I35: =SUM(I30:I34) -> 23952.885 | Y35: =SUM(Y30:Y34) -> 0 | Z35: =SUM(Z30:Z34) -> 3.3 | AA35: =SUM(AA30:AA34) -> 3.3 | AB35: =SUM(AB30:AB34) -> 17.39 | AC35: =SUM(AC30:AC34) -> 0 | AD35: =SUM(AD30:AD34) -> 2626.767 | AE35: =SUM(AE30:AE34) -> 2626.767 | AF35: =SUM(AF30:AF34) -> 21326.118 | AG35: =BA35 -> 0.12 | AH35: =SUM(AH30:AH34) -> 0 | AI35: 0 | BA35: =SUM(BA30:BA34)/COUNT(BA30:BA34) -> 0.12 | BC35: =SUM(BC30:BC34)/COUNT(BC30:BC34) -> 0 | BD35: =SUM(BD30:BD34)/COUNT(BD30:BD34) -> 0 | BE35: =SUM(BE30:BE34)/COUNT(BE30:BE34) -> 0 | BF35: =SUM(BF30:BF34)/COUNT(BF30:BF34) -> 0 | BG35: =SUM(BG30:BG34)/COUNT(BG30:BG34) -> 0 | BH35: =SUM(BH30:BH34)/COUNT(BH30:BH34) -> 0 | BI35: =SUM(BI30:BI34)/COUNT(BI30:BI34) -> 0 | BJ35: =SUM(BJ30:BJ34)/COUNT(BJ30:BJ34) -> 0
B36: Kitchen Area ( Storage Cabinets ) | AG36: =BA36 -> 0
B37: 3/4'' Marine Plywood | C37: 62.89 | D37: =C37*$L$23 -> 69.179 | E37: sq.m | F37: ='Material and Labor Cost'!$D$21 -> 576 | G37: ='Material and Labor Cost'!$F$21 -> 300 | H37: =SUM(F37:G37) -> 876 | I37: =H37*D37 -> 60600.804 | Y37: =SUM(AI37:AP37) -> 0 | Z37: =D37*AG37 -> 20.7537 | AA37: =SUM(Y37:Z37) -> 20.7537 | AB37: =D37-AA37 -> 48.4253 | AC37: =SUM(AR36:AY36) -> 0 | AD37: =AG37*I37 -> 18180.241 | AE37: =SUM(AC37:AD37) -> 18180.241 | AF37: =I37-AE37 -> 42420.563 | AG37: =BA37 -> 0.3 | AI37: 0 | BA37: 0.3 | BC37: =SUM(BS36:BZ36) -> 0 | BD37: =SUM(BN36:BT36) -> 0 | BE37: =SUM(BU36:CB36) -> 0 | BF37: =SUM(BV36:CC36) -> 0 | BG37: =SUM(BW36:CD36) -> 0 | BH37: =SUM(BX36:CE36) -> 0 | BI37: =SUM(BY36:CF36) -> 0 | BJ37: =SUM(BZ36:CG36) -> 0
B38: 1/2'' Backing Marine plywood | C38: 7.9 | D38: =C38*$L$23 -> 8.69 | E38: sq.m | F38: ='Material and Labor Cost'!$D$23 -> 330 | G38: ='Material and Labor Cost'!$F$23 -> 165 | H38: =SUM(F38:G38) -> 495 | I38: =H38*D38 -> 4301.55 | Y38: =SUM(AI38:AP38) -> 0 | Z38: =D38*AG38 -> 2.607 | AA38: =SUM(Y38:Z38) -> 2.607 | AB38: =D38-AA38 -> 6.083 | AC38: =SUM(AR37:AY37) -> 0 | AD38: =AG38*I38 -> 1290.465 | AE38: =SUM(AC38:AD38) -> 1290.465 | AF38: =I38-AE38 -> 3011.085 | AG38: =BA38 -> 0.3 | AI38: 0 | BA38: 0.3 | BC38: =SUM(BS37:BZ37) -> 0 | BD38: =SUM(BN37:BT37) -> 0 | BE38: =SUM(BU37:CB37) -> 0 | BF38: =SUM(BV37:CC37) -> 0 | BG38: =SUM(BW37:CD37) -> 0 | BH38: =SUM(BX37:CE37) -> 0 | BI38: =SUM(BY37:CF37) -> 0 | BJ38: =SUM(BZ37:CG37) -> 0
B39: Paint Finish | C39: 50.312 | D39: =C39*$L$23 -> 55.3432 | E39: sq.m | F39: ='Material and Labor Cost'!$D$25 -> 555 | G39: ='Material and Labor Cost'!$F$25 -> 275 | H39: =SUM(F39:G39) -> 830 | I39: =H39*D39 -> 45934.856 | Y39: =SUM(AI39:AP39) -> 0 | Z39: =D39*AG39 -> 0 | AA39: =SUM(Y39:Z39) -> 0 | AB39: =D39-AA39 -> 55.3432 | AC39: =SUM(AR38:AY38) -> 0 | AD39: =AG39*I39 -> 0 | AE39: =SUM(AC39:AD39) -> 0 | AF39: =I39-AE39 -> 45934.856 | AG39: =BA39 -> 0 | AI39: 0 | BA39: =SUM(BK38:BQ38) -> 0 | BC39: =SUM(BS38:BZ38) -> 0 | BD39: =SUM(BN38:BT38) -> 0 | BE39: =SUM(BU38:CB38) -> 0 | BF39: =SUM(BV38:CC38) -> 0 | BG39: =SUM(BW38:CD38) -> 0 | BH39: =SUM(BX38:CE38) -> 0 | BI39: =SUM(BY38:CF38) -> 0 | BJ39: =SUM(BZ38:CG38) -> 0
B40: Quartz White sintered stone | C40: 1.79 | D40: =C40*$L$23 -> 1.969 | E40: sq.m | F40: ='Material and Labor Cost'!$D$27 -> 6600 | G40: ='Material and Labor Cost'!$F$27 -> 3300 | H40: =SUM(F40:G40) -> 9900 | I40: =H40*D40 -> 19493.1 | Y40: =SUM(AI40:AP40) -> 0 | Z40: =D40*AG40 -> 0 | AA40: =SUM(Y40:Z40) -> 0 | AB40: =D40-AA40 -> 1.969 | AC40: =SUM(AR39:AY39) -> 0 | AD40: =AG40*I40 -> 0 | AE40: =SUM(AC40:AD40) -> 0 | AF40: =I40-AE40 -> 19493.1 | AG40: =BA40 -> 0 | AI40: 0 | BA40: =SUM(BK39:BQ39) -> 0 | BC40: =SUM(BS39:BZ39) -> 0 | BD40: =SUM(BN39:BT39) -> 0 | BE40: =SUM(BU39:CB39) -> 0 | BF40: =SUM(BV39:CC39) -> 0 | BG40: =SUM(BW39:CD39) -> 0 | BH40: =SUM(BX39:CE39) -> 0 | BI40: =SUM(BY39:CF39) -> 0 | BJ40: =SUM(BZ39:CG39) -> 0
B41: Miscellaneous and other Consumables | D41: 1 | E41: lot | I41: =SUM(I37:I40)*$L$27 -> 15639.637 | Y41: =SUM(AI41:AP41) -> 0 | Z41: =D41*AG41 -> 0 | AA41: =SUM(Y41:Z41) -> 0 | AB41: =D41-AA41 -> 1 | AC41: =SUM(AR40:AY40) -> 0 | AD41: =AG41*I41 -> 0 | AE41: =SUM(AC41:AD41) -> 0 | AF41: =I41-AE41 -> 15639.637 | AG41: =BA41 -> 0 | AI41: 0 | BA41: =SUM(BK40:BQ40) -> 0 | BC41: =SUM(BS40:BZ40) -> 0 | BD41: =SUM(BN40:BT40) -> 0 | BE41: =SUM(BU40:CB40) -> 0 | BF41: =SUM(BV40:CC40) -> 0 | BG41: =SUM(BW40:CD40) -> 0 | BH41: =SUM(BX40:CE40) -> 0 | BI41: =SUM(BY40:CF40) -> 0 | BJ41: =SUM(BZ40:CG40) -> 0
B42: Kitchen Area ( Storage Cabinets ) Sub-total: | I42: =SUM(I37:I41) -> 145969.95 | Y42: =SUM(Y37:Y41) -> 0 | Z42: =SUM(Z37:Z41) -> 23.3607 | AA42: =SUM(AA37:AA41) -> 23.3607 | AB42: =SUM(AB37:AB41) -> 112.8205 | AC42: =SUM(AC37:AC41) -> 0 | AD42: =SUM(AD37:AD41) -> 19470.706 | AE42: =SUM(AE37:AE41) -> 19470.706 | AF42: =SUM(AF37:AF41) -> 126499.24 | AG42: =BA42 -> 0.12 | AI42: 0 | BA42: =SUM(BA37:BA41)/COUNT(BA37:BA41) -> 0.12 | BC42: =SUM(BC37:BC41)/COUNT(BC37:BC41) -> 0 | BD42: =SUM(BD37:BD41)/COUNT(BD37:BD41) -> 0 | BE42: =SUM(BE37:BE41)/COUNT(BE37:BE41) -> 0 | BF42: =SUM(BF37:BF41)/COUNT(BF37:BF41) -> 0 | BG42: =SUM(BG37:BG41)/COUNT(BG37:BG41) -> 0 | BH42: =SUM(BH37:BH41)/COUNT(BH37:BH41) -> 0 | BI42: =SUM(BI37:BI41)/COUNT(BI37:BI41) -> 0 | BJ42: =SUM(BJ37:BJ41)/COUNT(BJ37:BJ41) -> 0
B43: Kitchen Area ( Counter Top ) | AG43: =BA43 -> 0
B44: 3/4'' Marine Plywood | C44: 18.04 | D44: =C44*$L$23 -> 19.844 | E44: sq.m | F44: ='Material and Labor Cost'!$D$21 -> 576 | G44: ='Material and Labor Cost'!$F$21 -> 300 | H44: =SUM(F44:G44) -> 876 | I44: =H44*D44 -> 17383.344 | Y44: =SUM(AI44:AP44) -> 0 | Z44: =D44*AG44 -> 5.9532 | AA44: =SUM(Y44:Z44) -> 5.9532 | AB44: =D44-AA44 -> 13.8908 | AC44: =SUM(AR43:AY43) -> 0 | AD44: =AG44*I44 -> 5215.0032 | AE44: =SUM(AC44:AD44) -> 5215.0032 | AF44: =I44-AE44 -> 12168.341 | AG44: =BA44 -> 0.3 | AI44: 0 | BA44: 0.3 | BC44: =SUM(BS43:BZ43) -> 0 | BD44: =SUM(BN43:BT43) -> 0 | BE44: =SUM(BU43:CB43) -> 0 | BF44: =SUM(BV43:CC43) -> 0 | BG44: =SUM(BW43:CD43) -> 0 | BH44: =SUM(BX43:CE43) -> 0 | BI44: =SUM(BY43:CF43) -> 0 | BJ44: =SUM(BZ43:CG43) -> 0
B45: 1/2'' Backing Marine plywood | C45: 2.6 | D45: =C45*$L$23 -> 2.86 | E45: sq.m | F45: ='Material and Labor Cost'!$D$23 -> 330 | G45: ='Material and Labor Cost'!$F$23 -> 165 | H45: =SUM(F45:G45) -> 495 | I45: =H45*D45 -> 1415.7 | Y45: =SUM(AI45:AP45) -> 0 | Z45: =D45*AG45 -> 0.858 | AA45: =SUM(Y45:Z45) -> 0.858 | AB45: =D45-AA45 -> 2.002 | AC45: =SUM(AR44:AY44) -> 0 | AD45: =AG45*I45 -> 424.71 | AE45: =SUM(AC45:AD45) -> 424.71 | AF45: =I45-AE45 -> 990.99 | AG45: =BA45 -> 0.3 | AI45: 0 | BA45: 0.3 | BC45: =SUM(BS44:BZ44) -> 0 | BD45: =SUM(BN44:BT44) -> 0 | BE45: =SUM(BU44:CB44) -> 0 | BF45: =SUM(BV44:CC44) -> 0 | BG45: =SUM(BW44:CD44) -> 0 | BH45: =SUM(BX44:CE44) -> 0 | BI45: =SUM(BY44:CF44) -> 0 | BJ45: =SUM(BZ44:CG44) -> 0
B46: Paint Finish | C46: =C44-C45 -> 15.44 | D46: =C46*$L$23 -> 16.984 | E46: sq.m | F46: ='Material and Labor Cost'!$D$25 -> 555 | G46: ='Material and Labor Cost'!$F$25 -> 275 | H46: =SUM(F46:G46) -> 830 | I46: =H46*D46 -> 14096.72 | Y46: =SUM(AI46:AP46) -> 0 | Z46: =D46*AG46 -> 0 | AA46: =SUM(Y46:Z46) -> 0 | AB46: =D46-AA46 -> 16.984 | AC46: =SUM(AR45:AY45) -> 0 | AD46: =AG46*I46 -> 0 | AE46: =SUM(AC46:AD46) -> 0 | AF46: =I46-AE46 -> 14096.72 | AG46: =BA46 -> 0 | AI46: 0 | BA46: =SUM(BK45:BQ45) -> 0 | BC46: =SUM(BS45:BZ45) -> 0 | BD46: =SUM(BN45:BT45) -> 0 | BE46: =SUM(BU45:CB45) -> 0 | BF46: =SUM(BV45:CC45) -> 0 | BG46: =SUM(BW45:CD45) -> 0 | BH46: =SUM(BX45:CE45) -> 0 | BI46: =SUM(BY45:CF45) -> 0 | BJ46: =SUM(BZ45:CG45) -> 0
B47: Quartz White sintered stone | C47: 5.4 | D47: =C47*$L$23 -> 5.94 | E47: sq.m | F47: ='Material and Labor Cost'!$D$27 -> 6600 | G47: ='Material and Labor Cost'!$F$27 -> 3300 | H47: =SUM(F47:G47) -> 9900 | I47: =H47*D47 -> 58806 | Y47: =SUM(AI47:AP47) -> 0 | Z47: =D47*AG47 -> 0 | AA47: =SUM(Y47:Z47) -> 0 | AB47: =D47-AA47 -> 5.94 | AC47: =SUM(AR46:AY46) -> 0 | AD47: =AG47*I47 -> 0 | AE47: =SUM(AC47:AD47) -> 0 | AF47: =I47-AE47 -> 58806 | AG47: =BA47 -> 0 | AI47: 0 | BA47: =SUM(BK46:BQ46) -> 0 | BC47: =SUM(BS46:BZ46) -> 0 | BD47: =SUM(BN46:BT46) -> 0 | BE47: =SUM(BU46:CB46) -> 0 | BF47: =SUM(BV46:CC46) -> 0 | BG47: =SUM(BW46:CD46) -> 0 | BH47: =SUM(BX46:CE46) -> 0 | BI47: =SUM(BY46:CF46) -> 0 | BJ47: =SUM(BZ46:CG46) -> 0
B48: Miscellaneous and other Consumables | D48: 1 | E48: lot | I48: =SUM(I44:I47)*$L$27 -> 11004.212 | Y48: =SUM(AI48:AP48) -> 0 | Z48: =D48*AG48 -> 0 | AA48: =SUM(Y48:Z48) -> 0 | AB48: =D48-AA48 -> 1 | AC48: =SUM(AR47:AY47) -> 0 | AD48: =AG48*I48 -> 0 | AE48: =SUM(AC48:AD48) -> 0 | AF48: =I48-AE48 -> 11004.212 | AG48: =BA48 -> 0 | AI48: 0 | BA48: =SUM(BK47:BQ47) -> 0 | BC48: =SUM(BS47:BZ47) -> 0 | BD48: =SUM(BN47:BT47) -> 0 | BE48: =SUM(BU47:CB47) -> 0 | BF48: =SUM(BV47:CC47) -> 0 | BG48: =SUM(BW47:CD47) -> 0 | BH48: =SUM(BX47:CE47) -> 0 | BI48: =SUM(BY47:CF47) -> 0 | BJ48: =SUM(BZ47:CG47) -> 0
B49: Kitchen Area ( Counter Top ) Sub-total: | I49: =SUM(I44:I48) -> 102705.98 | Y49: =SUM(Y44:Y48) -> 0 | Z49: =SUM(Z44:Z48) -> 6.8112 | AA49: =SUM(AA44:AA48) -> 6.8112 | AB49: =SUM(AB44:AB48) -> 39.8168 | AC49: =SUM(AC44:AC48) -> 0 | AD49: =SUM(AD44:AD48) -> 5639.7132 | AE49: =SUM(AE44:AE48) -> 5639.7132 | AF49: =SUM(AF44:AF48) -> 97066.262 | AG49: =BA49 -> 0.12 | AI49: 0 | BA49: =SUM(BA44:BA48)/COUNT(BA44:BA48) -> 0.12 | BC49: =SUM(BC44:BC48)/COUNT(BC44:BC48) -> 0 | BD49: =SUM(BD44:BD48)/COUNT(BD44:BD48) -> 0 | BE49: =SUM(BE44:BE48)/COUNT(BE44:BE48) -> 0 | BF49: =SUM(BF44:BF48)/COUNT(BF44:BF48) -> 0 | BG49: =SUM(BG44:BG48)/COUNT(BG44:BG48) -> 0 | BH49: =SUM(BH44:BH48)/COUNT(BH44:BH48) -> 0 | BI49: =SUM(BI44:BI48)/COUNT(BI44:BI48) -> 0 | BJ49: =SUM(BJ44:BJ48)/COUNT(BJ44:BJ48) -> 0
B50: Powder Room (Lavatory Cabinets) | AG50: =BA50 -> 0
B51: 3/4'' Marine Plywood | C51: 4.46 | D51: =C51*$L$23 -> 4.906 | E51: sq.m | F51: ='Material and Labor Cost'!$D$21 -> 576 | G51: ='Material and Labor Cost'!$F$21 -> 300 | H51: =SUM(F51:G51) -> 876 | I51: =H51*D51 -> 4297.656 | L51: Miscellaneous | Y51: =SUM(AI51:AP51) -> 0 | Z51: =D51*AG51 -> 3.9248 | AA51: =SUM(Y51:Z51) -> 3.9248 | AB51: =D51-AA51 -> 0.9812 | AC51: =SUM(AR50:AY50) -> 0 | AD51: =AG51*I51 -> 3438.1248 | AE51: =SUM(AC51:AD51) -> 3438.1248 | AF51: =I51-AE51 -> 859.5312 | AG51: =BA51 -> 0.8 | AI51: 0 | BA51: 0.8 | BC51: =SUM(BS50:BZ50) -> 0 | BD51: =SUM(BN50:BT50) -> 0 | BE51: =SUM(BU50:CB50) -> 0 | BF51: =SUM(BV50:CC50) -> 0 | BG51: =SUM(BW50:CD50) -> 0 | BH51: =SUM(BX50:CE50) -> 0 | BI51: =SUM(BY50:CF50) -> 0 | BJ51: =SUM(BZ50:CG50) -> 0
B52: 1/2'' Backing Marine plywood | C52: 0.6 | D52: =C52*$L$23 -> 0.66 | E52: sq.m | F52: ='Material and Labor Cost'!$D$23 -> 330 | G52: ='Material and Labor Cost'!$F$23 -> 165 | H52: =SUM(F52:G52) -> 495 | I52: =H52*D52 -> 326.7 | L52: 0.4 | Y52: =SUM(AI52:AP52) -> 0 | Z52: =D52*AG52 -> 0.528 | AA52: =SUM(Y52:Z52) -> 0.528 | AB52: =D52-AA52 -> 0.132 | AC52: =SUM(AR51:AY51) -> 0 | AD52: =AG52*I52 -> 261.36 | AE52: =SUM(AC52:AD52) -> 261.36 | AF52: =I52-AE52 -> 65.34 | AG52: =BA52 -> 0.8 | AI52: 0 | BA52: 0.8 | BC52: =SUM(BS51:BZ51) -> 0 | BD52: =SUM(BN51:BT51) -> 0 | BE52: =SUM(BU51:CB51) -> 0 | BF52: =SUM(BV51:CC51) -> 0 | BG52: =SUM(BW51:CD51) -> 0 | BH52: =SUM(BX51:CE51) -> 0 | BI52: =SUM(BY51:CF51) -> 0 | BJ52: =SUM(BZ51:CG51) -> 0
...

Sheet DOORS & WINDOW, PLUMBING, WOODE
A13: Project name : | B13: PROPOSED THREE STORY RESIDENCE
A14: Location : | B14: GRAND CENTENIAL HOMES KAWIT CAVITE
A15: Date : | B15: =TODAY() -> 46251
T16: QUANTITY | AC16: AMOUNT | AL16: ACCOMPLISHMENT | AN16: PREVIOUS ACCOMPLISHMENT
A17: ITEM NO | B17: Description | C17: QUANTITY | D17: UNIT | E17: Material Cost Php/unit | F17: Labor and Equipment Cost Php/unit | G17: Total Cost Php/Unit | H17: Total Amount Php | J17: QUANTITY | N17: AMOUNT | R17: PERCENTAGE | T17: BILLING 1 | U17: BILLING 2 | V17: BILLING 3 | W17: BILLING 4 | X17: BILLING 5 | Y17: BILLING 6 | Z17: BILLING 7 | AA17: BILLING 8 | AC17: BILLING 1 | AD17: BILLING 2 | AE17: BILLING 3 | AF17: BILLING 4 | AG17: BILLING 5 | AH17: BILLING 6 | AI17: BILLING 7 | AJ17: BILLING 8 | AL17: BILLING | AN17: BILLING 1 | AO17: BILLING 2 | AP17: BILLING 3 | AQ17: BILLING 4 | AR17: BILLING 5 | AS17: BILLING 6 | AT17: BILLING 7 | AU17: BILLING 8
B18: DOORS ( Door Jamb included) | J18: PREVIOUS | K18: THIS DATE | L18: TO DATE | M18: BALANCE | N18: PREVIOUS | O18: THIS DATE | P18: TO DATE | Q18: BALANCE | R18: Accomplishment
